Workbook

Sheet 00_DAFTAR_ISI
A1: 📚 PAKET 4: KHUSUS 95 RUMUS STATISTIKA EXCEL LENGKAP (95 SHEET RUMUS • 1 CONTOH + 5 SOAL TES PER RUMUS)
A2: Setiap Sheet berisi: 1 Contoh Soal + Jawaban Benar, lalu 5 Soal Tes Tanpa Kunci. Kunci Jawaban Lengkap ada di Sheet Paling Terakhir (99_KUNCI_JAWABAN)! | F2: 🔑 Buka 99_KUNCI_JAWABAN
A4: No | B4: Nama Rumus (Sheet) | C4: Kategori | D4: Sintaks Umum | E4: Fungsinya Buat Apa (Bahasa Bayi & Dunia Nyata) | F4: Link Buka Sheet
A5: 1 | B5: AVEDEV | C5: 8. Statistik & Analisis Data | D5: =AVEDEV(range_data) | E5: Menghitung rata-rata simpangan mutlak data dari nilai rata-ratanya. | F5: 👉 Buka Sheet AVEDEV
A6: 2 | B6: AVERAGE | C6: 8. Statistik & Analisis Data | D6: =AVERAGE(range_data) | E6: Menghitung nilai RATA-RATA (Mean) dari sekumpulan angka. | F6: 👉 Buka Sheet AVERAGE
A7: 3 | B7: AVERAGEA | C7: 8. Statistik & Analisis Data | D7: =AVERAGEA(range_data) | E7: Menghitung rata-rata dengan menyertakan sel teks (dihitung 0) dan logika. | F7: 👉 Buka Sheet AVERAGEA
A8: 4 | B8: AVERAGEIF | C8: 8. Statistik & Analisis Data | D8: =AVERAGEIF(range_syarat, syarat, [range_rata2]) | E8: Menghitung rata-rata HANYA untuk baris yang memenuhi 1 syarat tertentu. | F8: 👉 Buka Sheet AVERAGEIF
A9: 5 | B9: AVERAGEIFS | C9: 8. Statistik & Analisis Data | D9: =AVERAGEIFS(range_rata2, range_syarat1, syarat1, ...) | E9: Menghitung rata-rata dengan banyak syarat sekaligus. | F9: 👉 Buka Sheet AVERAGEIFS
A10: 6 | B10: BETA.DIST | C10: 8. Statistik & Analisis Data | D10: =BETA.DIST(x, alpha, beta, TRUE) | E10: Menghitung fungsi distribusi probabilitas Beta kumulatif. | F10: 👉 Buka Sheet BETA.DIST
A11: 7 | B11: BETA.INV | C11: 8. Statistik & Analisis Data | D11: =BETA.INV(probabilitas, alpha, beta) | E11: Menghitung invers dari fungsi distribusi probabilitas Beta kumulatif. | F11: 👉 Buka Sheet BETA.INV
A12: 8 | B12: BINOM.DIST | C12: 8. Statistik & Analisis Data | D12: =BINOM.DIST(sukses, cobaan, prob_sukses, TRUE) | E12: Menghitung peluang distribusi Binomial dari sejumlah percobaan independen. | F12: 👉 Buka Sheet BINOM.DIST
A13: 9 | B13: BINOM.INV | C13: 8. Statistik & Analisis Data | D13: =BINOM.INV(cobaan, prob_sukses, alpha) | E13: Mencari nilai terkecil sehingga distribusi binomial kumulatif >= alpha. | F13: 👉 Buka Sheet BINOM.INV
A14: 10 | B14: CHISQ.DIST | C14: 8. Statistik & Analisis Data | D14: =CHISQ.DIST(x, deg_freedom, TRUE) | E14: Menghasilkan distribusi probabilitas Chi-Square sisi kiri. | F14: 👉 Buka Sheet CHISQ.DIST
A15: 11 | B15: CHISQ.DIST.RT | C15: 8. Statistik & Analisis Data | D15: =CHISQ.DIST.RT(x, deg_freedom) | E15: Menghasilkan probabilitas ekor kanan (Right-Tailed) dari distribusi Chi-Square. | F15: 👉 Buka Sheet CHISQ.DIST.RT
A16: 12 | B16: CHISQ.INV | C16: 8. Statistik & Analisis Data | D16: =CHISQ.INV(probabilitas, deg_freedom) | E16: Menghasilkan nilai invers probabilitas ekor kiri dari distribusi Chi-Square. | F16: 👉 Buka Sheet CHISQ.INV
A17: 13 | B17: CHISQ.RT.INV | C17: 8. Statistik & Analisis Data | D17: =CHISQ.INV.RT(probabilitas, deg_freedom) | E17: Menghasilkan nilai invers probabilitas ekor kanan dari distribusi Chi-Square. | F17: 👉 Buka Sheet CHISQ.RT.INV
A18: 14 | B18: CHITEST | C18: 8. Statistik & Analisis Data | D18: =CHITEST(aktual_range, harapan_range) | E18: Menghitung uji independensi Chi-Square antara data aktual dan ekspektasi. | F18: 👉 Buka Sheet CHITEST
A19: 15 | B19: CONFIDENCE.NORM | C19: 8. Statistik & Analisis Data | D19: =CONFIDENCE.NORM(alpha, standard_dev, size) | E19: Menghitung rentang kepercayaan (margin of error) rata-rata populasi dengan distribusi normal. | F19: 👉 Buka Sheet CONFIDENCE.NORM
A20: 16 | B20: CONFIDENCE.T | C20: 8. Statistik & Analisis Data | D20: =CONFIDENCE.T(alpha, standard_dev, size) | E20: Menghitung rentang kepercayaan rata-rata populasi dengan distribusi Student's t. | F20: 👉 Buka Sheet CONFIDENCE.T
A21: 17 | B21: CORREL | C21: 8. Statistik & Analisis Data | D21: =CORREL(range_x, range_y) | E21: Mengukur koefisien korelasi (-1 s/d +1) antara dua variabel. | F21: 👉 Buka Sheet CORREL
A22: 18 | B22: COUNT | C22: 8. Statistik & Analisis Data | D22: =COUNT(range_data) | E22: Menghitung ada berapa banyak sel yang berisi ANGKA saja. | F22: 👉 Buka Sheet COUNT
A23: 19 | B23: COUNTA | C23: 8. Statistik & Analisis Data | D23: =COUNTA(range_data) | E23: Menghitung berapa banyak sel yang TIDAK KOSONG (berisi angka maupun teks). | F23: 👉 Buka Sheet COUNTA
A24: 20 | B24: COUNTBLANK | C24: 8. Statistik & Analisis Data | D24: =COUNTBLANK(range_data) | E24: Menghitung berapa banyak sel yang masih KOSONG (belum diisi). | F24: 👉 Buka Sheet COUNTBLANK
A25: 21 | B25: COUNTIF | C25: 8. Statistik & Analisis Data | D25: =COUNTIF(range_data, syarat) | E25: Menghitung jumlah sel yang memenuhi 1 kriteria tertentu. | F25: 👉 Buka Sheet COUNTIF
A26: 22 | B26: COUNTIFS | C26: 8. Statistik & Analisis Data | D26: =COUNTIFS(range1, syarat1, range2, syarat2) | E26: Menghitung jumlah baris data yang memenuhi banyak kriteria sekaligus. | F26: 👉 Buka Sheet COUNTIFS
A27: 23 | B27: COVARIANCE.P | C27: 8. Statistik & Analisis Data | D27: =COVARIANCE.P(range_x, range_y) | E27: Menghitung kovarians populasi antara dua kumpulan data. | F27: 👉 Buka Sheet COVARIANCE.P
A28: 24 | B28: COVARIANCE.T | C28: 8. Statistik & Analisis Data | D28: =COVARIANCE.S(range_x, range_y) | E28: Menghitung kovarians sampel antara dua variabel pengamatan. | F28: 👉 Buka Sheet COVARIANCE.T
A29: 25 | B29: CRITBINOM | C29: 8. Statistik & Analisis Data | D29: =CRITBINOM(cobaan, prob_sukses, alpha) | E29: Mencari nilai batas kritis distribusi binomial kumulatif. | F29: 👉 Buka Sheet CRITBINOM
A30: 26 | B30: DEVSQ | C30: 8. Statistik & Analisis Data | D30: =DEVSQ(range_data) | E30: Menghitung jumlah kuadrat simpangan data dari rata-ratanya. | F30: 👉 Buka Sheet DEVSQ
A31: 27 | B31: EXPON.DIST | C31: 8. Statistik & Analisis Data | D31: =EXPON.DIST(x, lambda, TRUE) | E31: Menghitung distribusi eksponensial (untuk memodelkan waktu tunggu antar-kejadian). | F31: 👉 Buka Sheet EXPON.DIST
A32: 28 | B32: F.DIST | C32: 8. Statistik & Analisis Data | D32: =F.DIST(x, deg_freedom1, deg_freedom2, TRUE) | E32: Menghitung distribusi probabilitas F untuk membandingkan tingkat keragaman. | F32: 👉 Buka Sheet F.DIST
A33: 29 | B33: F.DIST.RT | C33: 8. Statistik & Analisis Data | D33: =F.DIST.RT(x, deg_freedom1, deg_freedom2) | E33: Menghitung distribusi probabilitas F ekor kanan (Right-Tailed). | F33: 👉 Buka Sheet F.DIST.RT
A34: 30 | B34: F.INV | C34: 8. Statistik & Analisis Data | D34: =F.INV(probabilitas, deg_freedom1, deg_freedom2) | E34: Menghitung nilai invers dari distribusi probabilitas F ekor kiri. | F34: 👉 Buka Sheet F.INV
A35: 31 | B35: F.INV.RT | C35: 8. Statistik & Analisis Data | D35: =F.INV.RT(probabilitas, deg_freedom1, deg_freedom2) | E35: Menghitung nilai invers dari distribusi probabilitas F ekor kanan. | F35: 👉 Buka Sheet F.INV.RT
A36: 32 | B36: FTEST | C36: 8. Statistik & Analisis Data | D36: =FTEST(array1, array2) | E36: Menghasilkan hasil uji-F untuk membandingkan varians dari dua sampel data. | F36: 👉 Buka Sheet FTEST
A37: 33 | B37: FISHER | C37: 8. Statistik & Analisis Data | D37: =FISHER(x) | E37: Menghitung transformasi Fisher pada nilai koefisien korelasi r (-1 < x < 1). | F37: 👉 Buka Sheet FISHER
A38: 34 | B38: FISHER.INV | C38: 8. Statistik & Analisis Data | D38: =FISHERINV(y) | E38: Menghitung kebalikan (invers) dari transformasi Fisher. | F38: 👉 Buka Sheet FISHER.INV
A39: 35 | B39: FORECAST | C39: 8. Statistik & Analisis Data | D39: =FORECAST(target_x, range_y, range_x) | E39: Meramal nilai masa depan berdasarkan tren regresi linear. | F39: 👉 Buka Sheet FORECAST
A40: 36 | B40: FREQUENCY | C40: 8. Statistik & Analisis Data | D40: =FREQUENCY(data_array, bins_array) | E40: Menghitung distribusi frekuensi kemunculan data berdasarkan batas interval. | F40: 👉 Buka Sheet FREQUENCY
A41: 37 | B41: GAMMADIST | C41: 8. Statistik & Analisis Data | D41: =GAMMA.DIST(x, alpha, beta, TRUE) | E41: Menghitung distribusi Gamma untuk analisis variabel yang memiliki kemencengan. | F41: 👉 Buka Sheet GAMMADIST
...

Sheet AVEDEV
B1: 📊 #001 — RUMUS EXCEL: AVEDEV | Kategori: 8. Statistik & Analisis Data
B2: 1 Rumus = 1 Contoh Soal + Jawaban Benar & 5 Soal Tes Mandiri (Kunci Jawaban Ada di Sheet Paling Terakhir) | F2: ⬅️ Ke Daftar Isi (00_DAFTAR_ISI) | G2: 🔑 Ke Kunci Jawaban (Sheet Akhir)
B4: 1️⃣ IDENTITAS RUMUS & FUNGSINYA BUAT APA? (AVEDEV)
B5: Nama Rumus Excel | C5: =AVEDEV(...)
B6: Sintaks / Pola Umum | C6: =AVEDEV(range_data)
B7: 👶 Fungsinya Buat Apa? | C7: Menghitung rata-rata simpangan mutlak data dari nilai rata-ratanya.
B9: 2️⃣ 1 CONTOH SOAL & CONTOH JAWABAN BENAR (PELAJARI POLA RUMUS AVEDEV DI SINI)
B10: Nama Unit / Kategori | C10: Nilai Data | E10: ✅ 1 CONTOH SOAL BESERTA CONTOH RUMUS & HASIL JAWABAN BENAR:
B11: Simulasi Unit A | C11: 500000 | E11: Contoh Soal: | F11: Hitung hasil pengolahan fungsi AVEDEV untuk keempat baris data pada rentang C11:C14!
B12: Simulasi Unit B | C12: 750000 | E12: Contoh Rumus Benar: | F12: '=AVEDEV(C11:C14)
B13: Simulasi Unit C | C13: 600000 | E13: Contoh Hasil Benar: | F13: =AVEDEV(C11:C14)
B14: Simulasi Unit D | C14: 950000
B16: 3️⃣ 5 SOAL TES DUNIA NYATA — KERJAKAN DI KOTAK KUNING (TANPA KUNCI RUMUS / HASIL DI SINI!)
B17: 📌 Catatan Tes: Soal Tes #1 s/d #5 di bawah ini tidak menampilkan kunci rumus maupun hasil. Kunci jawaban lengkap tersedia di sheet paling terakhir (99_KUNCI_JAWABAN).
B19: 📝 SOAL TES #1: Kasus Keuangan & Akuntansi Kantor
B20: Nama Unit / Kategori | C20: Nilai Data | E20: Persoalan Tes #1: Hitung hasil pengolahan fungsi AVEDEV untuk keempat baris data pada rentang C21:C24!
B21: Cabang Jakarta | C21: 1250000 | E21: ✏️ KETIK RUMUS JAWABAN TES DI BAWAH: | F21: 📌 STATUS KOREKSI JAWABAN TES:
B22: Cabang Bandung | C22: 1850000 | F22: =IF(ISBLANK(E22), "⏳ Belum Diisi (Ketik Rumus di Sel Kuning E22)", IF(E22='99_KUNCI_JAWABAN'!F5, "✅ BENAR! JAWABAN TES TEPAT!", "❌ Belum Tepat (Cek Sheet Akhir: 99_KUNCI_JAWABAN)"))
B23: Cabang Surabaya | C23: 2100000
B24: Cabang Medan | C24: 1600000
B27: 📝 SOAL TES #2: Kasus HRD, Gaji & Lembur Karyawan
B28: Nama Unit / Kategori | C28: Nilai Data | E28: Persoalan Tes #2: Hitung hasil pengolahan fungsi AVEDEV untuk keempat baris data pada rentang C29:C32!
B29: Budi Santoso | C29: 4500000 | E29: ✏️ KETIK RUMUS JAWABAN TES DI BAWAH: | F29: 📌 STATUS KOREKSI JAWABAN TES:
B30: Siti Aminah | C30: 5200000 | F30: =IF(ISBLANK(E30), "⏳ Belum Diisi (Ketik Rumus di Sel Kuning E30)", IF(E30='99_KUNCI_JAWABAN'!F6, "✅ BENAR! JAWABAN TES TEPAT!", "❌ Belum Tepat (Cek Sheet Akhir: 99_KUNCI_JAWABAN)"))
B31: Andi Pratama | C31: 4800000
B32: Rina Wijaya | C32: 6100000
B35: 📝 SOAL TES #3: Kasus Logistik & Stok Gudang Utama
B36: Nama Unit / Kategori | C36: Nilai Data | E36: Persoalan Tes #3: Hitung hasil pengolahan fungsi AVEDEV untuk keempat baris data pada rentang C37:C40!
B37: Gudang Blok A | C37: 240 | E37: ✏️ KETIK RUMUS JAWABAN TES DI BAWAH: | F37: 📌 STATUS KOREKSI JAWABAN TES:
B38: Gudang Blok B | C38: 380 | F38: =IF(ISBLANK(E38), "⏳ Belum Diisi (Ketik Rumus di Sel Kuning E38)", IF(E38='99_KUNCI_JAWABAN'!F7, "✅ BENAR! JAWABAN TES TEPAT!", "❌ Belum Tepat (Cek Sheet Akhir: 99_KUNCI_JAWABAN)"))
B39: Gudang Blok C | C39: 195
B40: Gudang Blok D | C40: 425
B43: 📝 SOAL TES #4: Kasus Penjualan Retail & Target Toko
B44: Nama Unit / Kategori | C44: Nilai Data | E44: Persoalan Tes #4: Hitung hasil pengolahan fungsi AVEDEV untuk keempat baris data pada rentang C45:C48!
B45: Toko Elektronik | C45: 85 | E45: ✏️ KETIK RUMUS JAWABAN TES DI BAWAH: | F45: 📌 STATUS KOREKSI JAWABAN TES:
B46: Toko Komputer | C46: 92 | F46: =IF(ISBLANK(E46), "⏳ Belum Diisi (Ketik Rumus di Sel Kuning E46)", IF(E46='99_KUNCI_JAWABAN'!F8, "✅ BENAR! JAWABAN TES TEPAT!", "❌ Belum Tepat (Cek Sheet Akhir: 99_KUNCI_JAWABAN)"))
B47: Toko Aksesoris | C47: 78
B48: Toko Servis | C48: 95
B51: 📝 SOAL TES #5: Kasus Akademik Sekolah & Layanan Publik
B52: Nama Unit / Kategori | C52: Nilai Data | E52: Persoalan Tes #5: Hitung hasil pengolahan fungsi AVEDEV untuk keempat baris data pada rentang C53:C56!
...

Sheet AVERAGE
B1: 📊 #002 — RUMUS EXCEL: AVERAGE | Kategori: 8. Statistik & Analisis Data
B2: 1 Rumus = 1 Contoh Soal + Jawaban Benar & 5 Soal Tes Mandiri (Kunci Jawaban Ada di Sheet Paling Terakhir) | F2: ⬅️ Ke Daftar Isi (00_DAFTAR_ISI) | G2: 🔑 Ke Kunci Jawaban (Sheet Akhir)
B4: 1️⃣ IDENTITAS RUMUS & FUNGSINYA BUAT APA? (AVERAGE)
B5: Nama Rumus Excel | C5: =AVERAGE(...)
B6: Sintaks / Pola Umum | C6: =AVERAGE(range_data)
B7: 👶 Fungsinya Buat Apa? | C7: Menghitung nilai RATA-RATA (Mean) dari sekumpulan angka.
B9: 2️⃣ 1 CONTOH SOAL & CONTOH JAWABAN BENAR (PELAJARI POLA RUMUS AVERAGE DI SINI)
B10: Nama Unit / Kategori | C10: Nilai Data | E10: ✅ 1 CONTOH SOAL BESERTA CONTOH RUMUS & HASIL JAWABAN BENAR:
B11: Simulasi Unit A | C11: 500000 | E11: Contoh Soal: | F11: Hitung hasil pengolahan fungsi AVERAGE untuk keempat baris data pada rentang C11:C14!
B12: Simulasi Unit B | C12: 750000 | E12: Contoh Rumus Benar: | F12: '=AVERAGE(C11:C14)
B13: Simulasi Unit C | C13: 600000 | E13: Contoh Hasil Benar: | F13: =AVERAGE(C11:C14)
B14: Simulasi Unit D | C14: 950000
B16: 3️⃣ 5 SOAL TES DUNIA NYATA — KERJAKAN DI KOTAK KUNING (TANPA KUNCI RUMUS / HASIL DI SINI!)
B17: 📌 Catatan Tes: Soal Tes #1 s/d #5 di bawah ini tidak menampilkan kunci rumus maupun hasil. Kunci jawaban lengkap tersedia di sheet paling terakhir (99_KUNCI_JAWABAN).
B19: 📝 SOAL TES #1: Kasus Keuangan & Akuntansi Kantor
B20: Nama Unit / Kategori | C20: Nilai Data | E20: Persoalan Tes #1: Hitung hasil pengolahan fungsi AVERAGE untuk keempat baris data pada rentang C21:C24!
B21: Cabang Jakarta | C21: 1250000 | E21: ✏️ KETIK RUMUS JAWABAN TES DI BAWAH: | F21: 📌 STATUS KOREKSI JAWABAN TES:
B22: Cabang Bandung | C22: 1850000 | F22: =IF(ISBLANK(E22), "⏳ Belum Diisi (Ketik Rumus di Sel Kuning E22)", IF(E22='99_KUNCI_JAWABAN'!F10, "✅ BENAR! JAWABAN TES TEPAT!", "❌ Belum Tepat (Cek Sheet Akhir: 99_KUNCI_JAWABAN)"))
B23: Cabang Surabaya | C23: 2100000
B24: Cabang Medan | C24: 1600000
B27: 📝 SOAL TES #2: Kasus HRD, Gaji & Lembur Karyawan
B28: Nama Unit / Kategori | C28: Nilai Data | E28: Persoalan Tes #2: Hitung hasil pengolahan fungsi AVERAGE untuk keempat baris data pada rentang C29:C32!
B29: Budi Santoso | C29: 4500000 | E29: ✏️ KETIK RUMUS JAWABAN TES DI BAWAH: | F29: 📌 STATUS KOREKSI JAWABAN TES:
B30: Siti Aminah | C30: 5200000 | F30: =IF(ISBLANK(E30), "⏳ Belum Diisi (Ketik Rumus di Sel Kuning E30)", IF(E30='99_KUNCI_JAWABAN'!F11, "✅ BENAR! JAWABAN TES TEPAT!", "❌ Belum Tepat (Cek Sheet Akhir: 99_KUNCI_JAWABAN)"))
B31: Andi Pratama | C31: 4800000
B32: Rina Wijaya | C32: 6100000
B35: 📝 SOAL TES #3: Kasus Logistik & Stok Gudang Utama
B36: Nama Unit / Kategori | C36: Nilai Data | E36: Persoalan Tes #3: Hitung hasil pengolahan fungsi AVERAGE untuk keempat baris data pada rentang C37:C40!
B37: Gudang Blok A | C37: 240 | E37: ✏️ KETIK RUMUS JAWABAN TES DI BAWAH: | F37: 📌 STATUS KOREKSI JAWABAN TES:
B38: Gudang Blok B | C38: 380 | F38: =IF(ISBLANK(E38), "⏳ Belum Diisi (Ketik Rumus di Sel Kuning E38)", IF(E38='99_KUNCI_JAWABAN'!F12, "✅ BENAR! JAWABAN TES TEPAT!", "❌ Belum Tepat (Cek Sheet Akhir: 99_KUNCI_JAWABAN)"))
B39: Gudang Blok C | C39: 195
B40: Gudang Blok D | C40: 425
B43: 📝 SOAL TES #4: Kasus Penjualan Retail & Target Toko
B44: Nama Unit / Kategori | C44: Nilai Data | E44: Persoalan Tes #4: Hitung hasil pengolahan fungsi AVERAGE untuk keempat baris data pada rentang C45:C48!
B45: Toko Elektronik | C45: 85 | E45: ✏️ KETIK RUMUS JAWABAN TES DI BAWAH: | F45: 📌 STATUS KOREKSI JAWABAN TES:
B46: Toko Komputer | C46: 92 | F46: =IF(ISBLANK(E46), "⏳ Belum Diisi (Ketik Rumus di Sel Kuning E46)", IF(E46='99_KUNCI_JAWABAN'!F13, "✅ BENAR! JAWABAN TES TEPAT!", "❌ Belum Tepat (Cek Sheet Akhir: 99_KUNCI_JAWABAN)"))
B47: Toko Aksesoris | C47: 78
B48: Toko Servis | C48: 95
B51: 📝 SOAL TES #5: Kasus Akademik Sekolah & Layanan Publik
B52: Nama Unit / Kategori | C52: Nilai Data | E52: Persoalan Tes #5: Hitung hasil pengolahan fungsi AVERAGE untuk keempat baris data pada rentang C53:C56!
...

Sheet AVERAGEA
B1: 📊 #003 — RUMUS EXCEL: AVERAGEA | Kategori: 8. Statistik & Analisis Data
B2: 1 Rumus = 1 Contoh Soal + Jawaban Benar & 5 Soal Tes Mandiri (Kunci Jawaban Ada di Sheet Paling Terakhir) | F2: ⬅️ Ke Daftar Isi (00_DAFTAR_ISI) | G2: 🔑 Ke Kunci Jawaban (Sheet Akhir)
B4: 1️⃣ IDENTITAS RUMUS & FUNGSINYA BUAT APA? (AVERAGEA)
B5: Nama Rumus Excel | C5: =AVERAGEA(...)
B6: Sintaks / Pola Umum | C6: =AVERAGEA(range_data)
B7: 👶 Fungsinya Buat Apa? | C7: Menghitung rata-rata dengan menyertakan sel teks (dihitung 0) dan logika.
B9: 2️⃣ 1 CONTOH SOAL & CONTOH JAWABAN BENAR (PELAJARI POLA RUMUS AVERAGEA DI SINI)
B10: Nama Unit / Kategori | C10: Nilai Data | E10: ✅ 1 CONTOH SOAL BESERTA CONTOH RUMUS & HASIL JAWABAN BENAR:
B11: Simulasi Unit A | C11: 500000 | E11: Contoh Soal: | F11: Hitung hasil pengolahan fungsi AVERAGEA untuk keempat baris data pada rentang C11:C14!
B12: Simulasi Unit B | C12: 750000 | E12: Contoh Rumus Benar: | F12: '=AVERAGEA(C11:C14)
B13: Simulasi Unit C | C13: 600000 | E13: Contoh Hasil Benar: | F13: =AVERAGEA(C11:C14)
B14: Simulasi Unit D | C14: 950000
B16: 3️⃣ 5 SOAL TES DUNIA NYATA — KERJAKAN DI KOTAK KUNING (TANPA KUNCI RUMUS / HASIL DI SINI!)
B17: 📌 Catatan Tes: Soal Tes #1 s/d #5 di bawah ini tidak menampilkan kunci rumus maupun hasil. Kunci jawaban lengkap tersedia di sheet paling terakhir (99_KUNCI_JAWABAN).
B19: 📝 SOAL TES #1: Kasus Keuangan & Akuntansi Kantor
B20: Nama Unit / Kategori | C20: Nilai Data | E20: Persoalan Tes #1: Hitung hasil pengolahan fungsi AVERAGEA untuk keempat baris data pada rentang C21:C24!
B21: Cabang Jakarta | C21: 1250000 | E21: ✏️ KETIK RUMUS JAWABAN TES DI BAWAH: | F21: 📌 STATUS KOREKSI JAWABAN TES:
B22: Cabang Bandung | C22: 1850000 | F22: =IF(ISBLANK(E22), "⏳ Belum Diisi (Ketik Rumus di Sel Kuning E22)", IF(E22='99_KUNCI_JAWABAN'!F15, "✅ BENAR! JAWABAN TES TEPAT!", "❌ Belum Tepat (Cek Sheet Akhir: 99_KUNCI_JAWABAN)"))
B23: Cabang Surabaya | C23: 2100000
B24: Cabang Medan | C24: 1600000
B27: 📝 SOAL TES #2: Kasus HRD, Gaji & Lembur Karyawan
B28: Nama Unit / Kategori | C28: Nilai Data | E28: Persoalan Tes #2: Hitung hasil pengolahan fungsi AVERAGEA untuk keempat baris data pada rentang C29:C32!
B29: Budi Santoso | C29: 4500000 | E29: ✏️ KETIK RUMUS JAWABAN TES DI BAWAH: | F29: 📌 STATUS KOREKSI JAWABAN TES:
B30: Siti Aminah | C30: 5200000 | F30: =IF(ISBLANK(E30), "⏳ Belum Diisi (Ketik Rumus di Sel Kuning E30)", IF(E30='99_KUNCI_JAWABAN'!F16, "✅ BENAR! JAWABAN TES TEPAT!", "❌ Belum Tepat (Cek Sheet Akhir: 99_KUNCI_JAWABAN)"))
B31: Andi Pratama | C31: 4800000
B32: Rina Wijaya | C32: 6100000
B35: 📝 SOAL TES #3: Kasus Logistik & Stok Gudang Utama
B36: Nama Unit / Kategori | C36: Nilai Data | E36: Persoalan Tes #3: Hitung hasil pengolahan fungsi AVERAGEA untuk keempat baris data pada rentang C37:C40!
B37: Gudang Blok A | C37: 240 | E37: ✏️ KETIK RUMUS JAWABAN TES DI BAWAH: | F37: 📌 STATUS KOREKSI JAWABAN TES:
B38: Gudang Blok B | C38: 380 | F38: =IF(ISBLANK(E38), "⏳ Belum Diisi (Ketik Rumus di Sel Kuning E38)", IF(E38='99_KUNCI_JAWABAN'!F17, "✅ BENAR! JAWABAN TES TEPAT!", "❌ Belum Tepat (Cek Sheet Akhir: 99_KUNCI_JAWABAN)"))
B39: Gudang Blok C | C39: 195
B40: Gudang Blok D | C40: 425
B43: 📝 SOAL TES #4: Kasus Penjualan Retail & Target Toko
B44: Nama Unit / Kategori | C44: Nilai Data | E44: Persoalan Tes #4: Hitung hasil pengolahan fungsi AVERAGEA untuk keempat baris data pada rentang C45:C48!
B45: Toko Elektronik | C45: 85 | E45: ✏️ KETIK RUMUS JAWABAN TES DI BAWAH: | F45: 📌 STATUS KOREKSI JAWABAN TES:
B46: Toko Komputer | C46: 92 | F46: =IF(ISBLANK(E46), "⏳ Belum Diisi (Ketik Rumus di Sel Kuning E46)", IF(E46='99_KUNCI_JAWABAN'!F18, "✅ BENAR! JAWABAN TES TEPAT!", "❌ Belum Tepat (Cek Sheet Akhir: 99_KUNCI_JAWABAN)"))
B47: Toko Aksesoris | C47: 78
B48: Toko Servis | C48: 95
B51: 📝 SOAL TES #5: Kasus Akademik Sekolah & Layanan Publik
B52: Nama Unit / Kategori | C52: Nilai Data | E52: Persoalan Tes #5: Hitung hasil pengolahan fungsi AVERAGEA untuk keempat baris data pada rentang C53:C56!
...

Sheet AVERAGEIF
B1: 📊 #004 — RUMUS EXCEL: AVERAGEIF | Kategori: 8. Statistik & Analisis Data
B2: 1 Rumus = 1 Contoh Soal + Jawaban Benar & 5 Soal Tes Mandiri (Kunci Jawaban Ada di Sheet Paling Terakhir) | F2: ⬅️ Ke Daftar Isi (00_DAFTAR_ISI) | G2: 🔑 Ke Kunci Jawaban (Sheet Akhir)
B4: 1️⃣ IDENTITAS RUMUS & FUNGSINYA BUAT APA? (AVERAGEIF)
B5: Nama Rumus Excel | C5: =AVERAGEIF(...)
B6: Sintaks / Pola Umum | C6: =AVERAGEIF(range_syarat, syarat, [range_rata2])
B7: 👶 Fungsinya Buat Apa? | C7: Menghitung rata-rata HANYA untuk baris yang memenuhi 1 syarat tertentu.
B9: 2️⃣ 1 CONTOH SOAL & CONTOH JAWABAN BENAR (PELAJARI POLA RUMUS AVERAGEIF DI SINI)
B10: Kategori Lokasi | C10: Nilai Transaksi | E10: ✅ 1 CONTOH SOAL BESERTA CONTOH RUMUS & HASIL JAWABAN BENAR:
B11: Pusat | C11: 500000 | E11: Contoh Soal: | F11: Gunakan fungsi AVERAGEIF untuk mengolah data khusus kategori "Pusat" saja (rentang kategori di B11:B14 dan rentang nilai di C11:C14)!
B12: Cabang | C12: 750000 | E12: Contoh Rumus Benar: | F12: '=AVERAGEIF(B11:B14, "Pusat", C11:C14)
B13: Pusat | C13: 600000 | E13: Contoh Hasil Benar: | F13: =AVERAGEIF(B11:B14, "Pusat", C11:C14)
B14: Cabang | C14: 950000
B16: 3️⃣ 5 SOAL TES DUNIA NYATA — KERJAKAN DI KOTAK KUNING (TANPA KUNCI RUMUS / HASIL DI SINI!)
B17: 📌 Catatan Tes: Soal Tes #1 s/d #5 di bawah ini tidak menampilkan kunci rumus maupun hasil. Kunci jawaban lengkap tersedia di sheet paling terakhir (99_KUNCI_JAWABAN).
B19: 📝 SOAL TES #1: Kasus Keuangan & Akuntansi Kantor
B20: Kategori Lokasi | C20: Nilai Transaksi | E20: Persoalan Tes #1: Gunakan fungsi AVERAGEIF untuk mengolah data khusus kategori "Pusat" saja (rentang kategori di B21:B24 dan rentang nilai di C21:C24)!
B21: Pusat | C21: 1250000 | E21: ✏️ KETIK RUMUS JAWABAN TES DI BAWAH: | F21: 📌 STATUS KOREKSI JAWABAN TES:
B22: Cabang | C22: 1850000 | F22: =IF(ISBLANK(E22), "⏳ Belum Diisi (Ketik Rumus di Sel Kuning E22)", IF(E22='99_KUNCI_JAWABAN'!F20, "✅ BENAR! JAWABAN TES TEPAT!", "❌ Belum Tepat (Cek Sheet Akhir: 99_KUNCI_JAWABAN)"))
B23: Pusat | C23: 2100000
B24: Cabang | C24: 1600000
B27: 📝 SOAL TES #2: Kasus HRD, Gaji & Lembur Karyawan
B28: Kategori Lokasi | C28: Nilai Transaksi | E28: Persoalan Tes #2: Gunakan fungsi AVERAGEIF untuk mengolah data khusus kategori "Pusat" saja (rentang kategori di B29:B32 dan rentang nilai di C29:C32)!
B29: Pusat | C29: 4500000 | E29: ✏️ KETIK RUMUS JAWABAN TES DI BAWAH: | F29: 📌 STATUS KOREKSI JAWABAN TES:
B30: Cabang | C30: 5200000 | F30: =IF(ISBLANK(E30), "⏳ Belum Diisi (Ketik Rumus di Sel Kuning E30)", IF(E30='99_KUNCI_JAWABAN'!F21, "✅ BENAR! JAWABAN TES TEPAT!", "❌ Belum Tepat (Cek Sheet Akhir: 99_KUNCI_JAWABAN)"))
B31: Pusat | C31: 4800000
B32: Cabang | C32: 6100000
B35: 📝 SOAL TES #3: Kasus Logistik & Stok Gudang Utama
B36: Kategori Lokasi | C36: Nilai Transaksi | E36: Persoalan Tes #3: Gunakan fungsi AVERAGEIF untuk mengolah data khusus kategori "Pusat" saja (rentang kategori di B37:B40 dan rentang nilai di C37:C40)!
B37: Pusat | C37: 240 | E37: ✏️ KETIK RUMUS JAWABAN TES DI BAWAH: | F37: 📌 STATUS KOREKSI JAWABAN TES:
B38: Cabang | C38: 380 | F38: =IF(ISBLANK(E38), "⏳ Belum Diisi (Ketik Rumus di Sel Kuning E38)", IF(E38='99_KUNCI_JAWABAN'!F22, "✅ BENAR! JAWABAN TES TEPAT!", "❌ Belum Tepat (Cek Sheet Akhir: 99_KUNCI_JAWABAN)"))
B39: Pusat | C39: 195
B40: Cabang | C40: 425
B43: 📝 SOAL TES #4: Kasus Penjualan Retail & Target Toko
B44: Kategori Lokasi | C44: Nilai Transaksi | E44: Persoalan Tes #4: Gunakan fungsi AVERAGEIF untuk mengolah data khusus kategori "Pusat" saja (rentang kategori di B45:B48 dan rentang nilai di C45:C48)!
B45: Pusat | C45: 85 | E45: ✏️ KETIK RUMUS JAWABAN TES DI BAWAH: | F45: 📌 STATUS KOREKSI JAWABAN TES:
B46: Cabang | C46: 92 | F46: =IF(ISBLANK(E46), "⏳ Belum Diisi (Ketik Rumus di Sel Kuning E46)", IF(E46='99_KUNCI_JAWABAN'!F23, "✅ BENAR! JAWABAN TES TEPAT!", "❌ Belum Tepat (Cek Sheet Akhir: 99_KUNCI_JAWABAN)"))
B47: Pusat | C47: 78
B48: Cabang | C48: 95
B51: 📝 SOAL TES #5: Kasus Akademik Sekolah & Layanan Publik
B52: Kategori Lokasi | C52: Nilai Transaksi | E52: Persoalan Tes #5: Gunakan fungsi AVERAGEIF untuk mengolah data khusus kategori "Pusat" saja (rentang kategori di B53:B56 dan rentang nilai di C53:C56)!
...

Sheet AVERAGEIFS
B1: 📊 #005 — RUMUS EXCEL: AVERAGEIFS | Kategori: 8. Statistik & Analisis Data
B2: 1 Rumus = 1 Contoh Soal + Jawaban Benar & 5 Soal Tes Mandiri (Kunci Jawaban Ada di Sheet Paling Terakhir) | F2: ⬅️ Ke Daftar Isi (00_DAFTAR_ISI) | G2: 🔑 Ke Kunci Jawaban (Sheet Akhir)
B4: 1️⃣ IDENTITAS RUMUS & FUNGSINYA BUAT APA? (AVERAGEIFS)
B5: Nama Rumus Excel | C5: =AVERAGEIFS(...)
B6: Sintaks / Pola Umum | C6: =AVERAGEIFS(range_rata2, range_syarat1, syarat1, ...)
B7: 👶 Fungsinya Buat Apa? | C7: Menghitung rata-rata dengan banyak syarat sekaligus.
B9: 2️⃣ 1 CONTOH SOAL & CONTOH JAWABAN BENAR (PELAJARI POLA RUMUS AVERAGEIFS DI SINI)
B10: Status Unit | C10: Nilai Realisasi | E10: ✅ 1 CONTOH SOAL BESERTA CONTOH RUMUS & HASIL JAWABAN BENAR:
B11: Aktif | C11: 500000 | E11: Contoh Soal: | F11: Gunakan fungsi AVERAGEIFS untuk mengolah nilai di C11:C14 khusus baris yang berstatus "Aktif" pada kolom B11:B14!
B12: Aktif | C12: 750000 | E12: Contoh Rumus Benar: | F12: '=AVERAGEIFS(C11:C14, B11:B14, "Aktif")
B13: Nonaktif | C13: 600000 | E13: Contoh Hasil Benar: | F13: =AVERAGEIFS(C11:C14, B11:B14, "Aktif")
B14: Aktif | C14: 950000
B16: 3️⃣ 5 SOAL TES DUNIA NYATA — KERJAKAN DI KOTAK KUNING (TANPA KUNCI RUMUS / HASIL DI SINI!)
B17: 📌 Catatan Tes: Soal Tes #1 s/d #5 di bawah ini tidak menampilkan kunci rumus maupun hasil. Kunci jawaban lengkap tersedia di sheet paling terakhir (99_KUNCI_JAWABAN).
B19: 📝 SOAL TES #1: Kasus Keuangan & Akuntansi Kantor
B20: Status Unit | C20: Nilai Realisasi | E20: Persoalan Tes #1: Gunakan fungsi AVERAGEIFS untuk mengolah nilai di C21:C24 khusus baris yang berstatus "Aktif" pada kolom B21:B24!
B21: Aktif | C21: 1250000 | E21: ✏️ KETIK RUMUS JAWABAN TES DI BAWAH: | F21: 📌 STATUS KOREKSI JAWABAN TES:
B22: Aktif | C22: 1850000 | F22: =IF(ISBLANK(E22), "⏳ Belum Diisi (Ketik Rumus di Sel Kuning E22)", IF(E22='99_KUNCI_JAWABAN'!F25, "✅ BENAR! JAWABAN TES TEPAT!", "❌ Belum Tepat (Cek Sheet Akhir: 99_KUNCI_JAWABAN)"))
B23: Nonaktif | C23: 2100000
B24: Aktif | C24: 1600000
B27: 📝 SOAL TES #2: Kasus HRD, Gaji & Lembur Karyawan
B28: Status Unit | C28: Nilai Realisasi | E28: Persoalan Tes #2: Gunakan fungsi AVERAGEIFS untuk mengolah nilai di C29:C32 khusus baris yang berstatus "Aktif" pada kolom B29:B32!
B29: Aktif | C29: 4500000 | E29: ✏️ KETIK RUMUS JAWABAN TES DI BAWAH: | F29: 📌 STATUS KOREKSI JAWABAN TES:
B30: Aktif | C30: 5200000 | F30: =IF(ISBLANK(E30), "⏳ Belum Diisi (Ketik Rumus di Sel Kuning E30)", IF(E30='99_KUNCI_JAWABAN'!F26, "✅ BENAR! JAWABAN TES TEPAT!", "❌ Belum Tepat (Cek Sheet Akhir: 99_KUNCI_JAWABAN)"))
B31: Nonaktif | C31: 4800000
B32: Aktif | C32: 6100000
B35: 📝 SOAL TES #3: Kasus Logistik & Stok Gudang Utama
B36: Status Unit | C36: Nilai Realisasi | E36: Persoalan Tes #3: Gunakan fungsi AVERAGEIFS untuk mengolah nilai di C37:C40 khusus baris yang berstatus "Aktif" pada kolom B37:B40!
B37: Aktif | C37: 240 | E37: ✏️ KETIK RUMUS JAWABAN TES DI BAWAH: | F37: 📌 STATUS KOREKSI JAWABAN TES:
B38: Aktif | C38: 380 | F38: =IF(ISBLANK(E38), "⏳ Belum Diisi (Ketik Rumus di Sel Kuning E38)", IF(E38='99_KUNCI_JAWABAN'!F27, "✅ BENAR! JAWABAN TES TEPAT!", "❌ Belum Tepat (Cek Sheet Akhir: 99_KUNCI_JAWABAN)"))
B39: Nonaktif | C39: 195
B40: Aktif | C40: 425
B43: 📝 SOAL TES #4: Kasus Penjualan Retail & Target Toko
B44: Status Unit | C44: Nilai Realisasi | E44: Persoalan Tes #4: Gunakan fungsi AVERAGEIFS untuk mengolah nilai di C45:C48 khusus baris yang berstatus "Aktif" pada kolom B45:B48!
B45: Aktif | C45: 85 | E45: ✏️ KETIK RUMUS JAWABAN TES DI BAWAH: | F45: 📌 STATUS KOREKSI JAWABAN TES:
B46: Aktif | C46: 92 | F46: =IF(ISBLANK(E46), "⏳ Belum Diisi (Ketik Rumus di Sel Kuning E46)", IF(E46='99_KUNCI_JAWABAN'!F28, "✅ BENAR! JAWABAN TES TEPAT!", "❌ Belum Tepat (Cek Sheet Akhir: 99_KUNCI_JAWABAN)"))
B47: Nonaktif | C47: 78
B48: Aktif | C48: 95
B51: 📝 SOAL TES #5: Kasus Akademik Sekolah & Layanan Publik
B52: Status Unit | C52: Nilai Realisasi | E52: Persoalan Tes #5: Gunakan fungsi AVERAGEIFS untuk mengolah nilai di C53:C56 khusus baris yang berstatus "Aktif" pada kolom B53:B56!
...

Sheet BETA.DIST
B1: 📊 #006 — RUMUS EXCEL: BETA.DIST | Kategori: 8. Statistik & Analisis Data
B2: 1 Rumus = 1 Contoh Soal + Jawaban Benar & 5 Soal Tes Mandiri (Kunci Jawaban Ada di Sheet Paling Terakhir) | F2: ⬅️ Ke Daftar Isi (00_DAFTAR_ISI) | G2: 🔑 Ke Kunci Jawaban (Sheet Akhir)
B4: 1️⃣ IDENTITAS RUMUS & FUNGSINYA BUAT APA? (BETA.DIST)
B5: Nama Rumus Excel | C5: =BETA.DIST(...)
B6: Sintaks / Pola Umum | C6: =BETA.DIST(x, alpha, beta, TRUE)
B7: 👶 Fungsinya Buat Apa? | C7: Menghitung fungsi distribusi probabilitas Beta kumulatif.
B9: 2️⃣ 1 CONTOH SOAL & CONTOH JAWABAN BENAR (PELAJARI POLA RUMUS BETA.DIST DI SINI)
B10: Parameter Beta | C10: Nilai Input | E10: ✅ 1 CONTOH SOAL BESERTA CONTOH RUMUS & HASIL JAWABAN BENAR:
B11: Nilai X (C11) | C11: 0.8 | E11: Contoh Soal: | F11: Hitung distribusi Beta kumulatif menggunakan fungsi BETA.DIST dengan argumen C11, C12, C13, dan TRUE!
B12: Alpha (C12) | C12: 2 | E12: Contoh Rumus Benar: | F12: '=BETA.DIST(C11, C12, C13, TRUE)
B13: Beta (C13) | C13: 5 | E13: Contoh Hasil Benar: | F13: =BETA.DIST(C11, C12, C13, TRUE)
B14: Kumulatif | C14: 1
B16: 3️⃣ 5 SOAL TES DUNIA NYATA — KERJAKAN DI KOTAK KUNING (TANPA KUNCI RUMUS / HASIL DI SINI!)
B17: 📌 Catatan Tes: Soal Tes #1 s/d #5 di bawah ini tidak menampilkan kunci rumus maupun hasil. Kunci jawaban lengkap tersedia di sheet paling terakhir (99_KUNCI_JAWABAN).
B19: 📝 SOAL TES #1: Kasus Keuangan & Akuntansi Kantor
B20: Parameter Beta | C20: Nilai Input | E20: Persoalan Tes #1: Hitung distribusi Beta kumulatif menggunakan fungsi BETA.DIST dengan argumen C21, C22, C23, dan TRUE!
B21: Nilai X (C21) | C21: 0.3 | E21: ✏️ KETIK RUMUS JAWABAN TES DI BAWAH: | F21: 📌 STATUS KOREKSI JAWABAN TES:
B22: Alpha (C22) | C22: 2 | F22: =IF(ISBLANK(E22), "⏳ Belum Diisi (Ketik Rumus di Sel Kuning E22)", IF(E22='99_KUNCI_JAWABAN'!F30, "✅ BENAR! JAWABAN TES TEPAT!", "❌ Belum Tepat (Cek Sheet Akhir: 99_KUNCI_JAWABAN)"))
B23: Beta (C23) | C23: 5
B24: Kumulatif | C24: 1
B27: 📝 SOAL TES #2: Kasus HRD, Gaji & Lembur Karyawan
B28: Parameter Beta | C28: Nilai Input | E28: Persoalan Tes #2: Hitung distribusi Beta kumulatif menggunakan fungsi BETA.DIST dengan argumen C29, C30, C31, dan TRUE!
B29: Nilai X (C29) | C29: 0.4 | E29: ✏️ KETIK RUMUS JAWABAN TES DI BAWAH: | F29: 📌 STATUS KOREKSI JAWABAN TES:
B30: Alpha (C30) | C30: 2 | F30: =IF(ISBLANK(E30), "⏳ Belum Diisi (Ketik Rumus di Sel Kuning E30)", IF(E30='99_KUNCI_JAWABAN'!F31, "✅ BENAR! JAWABAN TES TEPAT!", "❌ Belum Tepat (Cek Sheet Akhir: 99_KUNCI_JAWABAN)"))
B31: Beta (C31) | C31: 5
B32: Kumulatif | C32: 1
B35: 📝 SOAL TES #3: Kasus Logistik & Stok Gudang Utama
B36: Parameter Beta | C36: Nilai Input | E36: Persoalan Tes #3: Hitung distribusi Beta kumulatif menggunakan fungsi BETA.DIST dengan argumen C37, C38, C39, dan TRUE!
B37: Nilai X (C37) | C37: 0.5 | E37: ✏️ KETIK RUMUS JAWABAN TES DI BAWAH: | F37: 📌 STATUS KOREKSI JAWABAN TES:
B38: Alpha (C38) | C38: 2 | F38: =IF(ISBLANK(E38), "⏳ Belum Diisi (Ketik Rumus di Sel Kuning E38)", IF(E38='99_KUNCI_JAWABAN'!F32, "✅ BENAR! JAWABAN TES TEPAT!", "❌ Belum Tepat (Cek Sheet Akhir: 99_KUNCI_JAWABAN)"))
B39: Beta (C39) | C39: 5
B40: Kumulatif | C40: 1
B43: 📝 SOAL TES #4: Kasus Penjualan Retail & Target Toko
B44: Parameter Beta | C44: Nilai Input | E44: Persoalan Tes #4: Hitung distribusi Beta kumulatif menggunakan fungsi BETA.DIST dengan argumen C45, C46, C47, dan TRUE!
B45: Nilai X (C45) | C45: 0.6 | E45: ✏️ KETIK RUMUS JAWABAN TES DI BAWAH: | F45: 📌 STATUS KOREKSI JAWABAN TES:
B46: Alpha (C46) | C46: 2 | F46: =IF(ISBLANK(E46), "⏳ Belum Diisi (Ketik Rumus di Sel Kuning E46)", IF(E46='99_KUNCI_JAWABAN'!F33, "✅ BENAR! JAWABAN TES TEPAT!", "❌ Belum Tepat (Cek Sheet Akhir: 99_KUNCI_JAWABAN)"))
B47: Beta (C47) | C47: 5
B48: Kumulatif | C48: 1
B51: 📝 SOAL TES #5: Kasus Akademik Sekolah & Layanan Publik
B52: Parameter Beta | C52: Nilai Input | E52: Persoalan Tes #5: Hitung distribusi Beta kumulatif menggunakan fungsi BETA.DIST dengan argumen C53, C54, C55, dan TRUE!
...

Sheet BETA.INV
B1: 📊 #007 — RUMUS EXCEL: BETA.INV | Kategori: 8. Statistik & Analisis Data
B2: 1 Rumus = 1 Contoh Soal + Jawaban Benar & 5 Soal Tes Mandiri (Kunci Jawaban Ada di Sheet Paling Terakhir) | F2: ⬅️ Ke Daftar Isi (00_DAFTAR_ISI) | G2: 🔑 Ke Kunci Jawaban (Sheet Akhir)
B4: 1️⃣ IDENTITAS RUMUS & FUNGSINYA BUAT APA? (BETA.INV)
B5: Nama Rumus Excel | C5: =BETA.INV(...)
B6: Sintaks / Pola Umum | C6: =BETA.INV(probabilitas, alpha, beta)
B7: 👶 Fungsinya Buat Apa? | C7: Menghitung invers dari fungsi distribusi probabilitas Beta kumulatif.
B9: 2️⃣ 1 CONTOH SOAL & CONTOH JAWABAN BENAR (PELAJARI POLA RUMUS BETA.INV DI SINI)
B10: Parameter Beta | C10: Nilai Input | E10: ✅ 1 CONTOH SOAL BESERTA CONTOH RUMUS & HASIL JAWABAN BENAR:
B11: Probabilitas (C11) | C11: 0.8 | E11: Contoh Soal: | F11: Hitung nilai invers distribusi Beta menggunakan fungsi BETA.INV dengan argumen C11, C12, dan C13!
B12: Alpha (C12) | C12: 2 | E12: Contoh Rumus Benar: | F12: '=BETA.INV(C11, C12, C13)
B13: Beta (C13) | C13: 5 | E13: Contoh Hasil Benar: | F13: =BETA.INV(C11, C12, C13)
B14: Cadangan | C14: 1
B16: 3️⃣ 5 SOAL TES DUNIA NYATA — KERJAKAN DI KOTAK KUNING (TANPA KUNCI RUMUS / HASIL DI SINI!)
B17: 📌 Catatan Tes: Soal Tes #1 s/d #5 di bawah ini tidak menampilkan kunci rumus maupun hasil. Kunci jawaban lengkap tersedia di sheet paling terakhir (99_KUNCI_JAWABAN).
B19: 📝 SOAL TES #1: Kasus Keuangan & Akuntansi Kantor
B20: Parameter Beta | C20: Nilai Input | E20: Persoalan Tes #1: Hitung nilai invers distribusi Beta menggunakan fungsi BETA.INV dengan argumen C21, C22, dan C23!
B21: Probabilitas (C21) | C21: 0.3 | E21: ✏️ KETIK RUMUS JAWABAN TES DI BAWAH: | F21: 📌 STATUS KOREKSI JAWABAN TES:
B22: Alpha (C22) | C22: 2 | F22: =IF(ISBLANK(E22), "⏳ Belum Diisi (Ketik Rumus di Sel Kuning E22)", IF(E22='99_KUNCI_JAWABAN'!F35, "✅ BENAR! JAWABAN TES TEPAT!", "❌ Belum Tepat (Cek Sheet Akhir: 99_KUNCI_JAWABAN)"))
B23: Beta (C23) | C23: 5
B24: Cadangan | C24: 1
B27: 📝 SOAL TES #2: Kasus HRD, Gaji & Lembur Karyawan
B28: Parameter Beta | C28: Nilai Input | E28: Persoalan Tes #2: Hitung nilai invers distribusi Beta menggunakan fungsi BETA.INV dengan argumen C29, C30, dan C31!
B29: Probabilitas (C29) | C29: 0.4 | E29: ✏️ KETIK RUMUS JAWABAN TES DI BAWAH: | F29: 📌 STATUS KOREKSI JAWABAN TES:
B30: Alpha (C30) | C30: 2 | F30: =IF(ISBLANK(E30), "⏳ Belum Diisi (Ketik Rumus di Sel Kuning E30)", IF(E30='99_KUNCI_JAWABAN'!F36, "✅ BENAR! JAWABAN TES TEPAT!", "❌ Belum Tepat (Cek Sheet Akhir: 99_KUNCI_JAWABAN)"))
B31: Beta (C31) | C31: 5
B32: Cadangan | C32: 1
B35: 📝 SOAL TES #3: Kasus Logistik & Stok Gudang Utama
B36: Parameter Beta | C36: Nilai Input | E36: Persoalan Tes #3: Hitung nilai invers distribusi Beta menggunakan fungsi BETA.INV dengan argumen C37, C38, dan C39!
B37: Probabilitas (C37) | C37: 0.5 | E37: ✏️ KETIK RUMUS JAWABAN TES DI BAWAH: | F37: 📌 STATUS KOREKSI JAWABAN TES:
B38: Alpha (C38) | C38: 2 | F38: =IF(ISBLANK(E38), "⏳ Belum Diisi (Ketik Rumus di Sel Kuning E38)", IF(E38='99_KUNCI_JAWABAN'!F37, "✅ BENAR! JAWABAN TES TEPAT!", "❌ Belum Tepat (Cek Sheet Akhir: 99_KUNCI_JAWABAN)"))
B39: Beta (C39) | C39: 5
B40: Cadangan | C40: 1
B43: 📝 SOAL TES #4: Kasus Penjualan Retail & Target Toko
B44: Parameter Beta | C44: Nilai Input | E44: Persoalan Tes #4: Hitung nilai invers distribusi Beta menggunakan fungsi BETA.INV dengan argumen C45, C46, dan C47!
B45: Probabilitas (C45) | C45: 0.6 | E45: ✏️ KETIK RUMUS JAWABAN TES DI BAWAH: | F45: 📌 STATUS KOREKSI JAWABAN TES:
B46: Alpha (C46) | C46: 2 | F46: =IF(ISBLANK(E46), "⏳ Belum Diisi (Ketik Rumus di Sel Kuning E46)", IF(E46='99_KUNCI_JAWABAN'!F38, "✅ BENAR! JAWABAN TES TEPAT!", "❌ Belum Tepat (Cek Sheet Akhir: 99_KUNCI_JAWABAN)"))
B47: Beta (C47) | C47: 5
B48: Cadangan | C48: 1
B51: 📝 SOAL TES #5: Kasus Akademik Sekolah & Layanan Publik
B52: Parameter Beta | C52: Nilai Input | E52: Persoalan Tes #5: Hitung nilai invers distribusi Beta menggunakan fungsi BETA.INV dengan argumen C53, C54, dan C55!
...

Sheet BINOM.DIST
B1: 📊 #008 — RUMUS EXCEL: BINOM.DIST | Kategori: 8. Statistik & Analisis Data
B2: 1 Rumus = 1 Contoh Soal + Jawaban Benar & 5 Soal Tes Mandiri (Kunci Jawaban Ada di Sheet Paling Terakhir) | F2: ⬅️ Ke Daftar Isi (00_DAFTAR_ISI) | G2: 🔑 Ke Kunci Jawaban (Sheet Akhir)
B4: 1️⃣ IDENTITAS RUMUS & FUNGSINYA BUAT APA? (BINOM.DIST)
B5: Nama Rumus Excel | C5: =BINOM.DIST(...)
B6: Sintaks / Pola Umum | C6: =BINOM.DIST(sukses, cobaan, prob_sukses, TRUE)
B7: 👶 Fungsinya Buat Apa? | C7: Menghitung peluang distribusi Binomial dari sejumlah percobaan independen.
B9: 2️⃣ 1 CONTOH SOAL & CONTOH JAWABAN BENAR (PELAJARI POLA RUMUS BINOM.DIST DI SINI)
B10: Parameter Binomial | C10: Nilai Input | E10: ✅ 1 CONTOH SOAL BESERTA CONTOH RUMUS & HASIL JAWABAN BENAR:
B11: Jumlah Sukses/Gagal (C11) | C11: 4 | E11: Contoh Soal: | F11: Hitung peluang distribusi kumulatif (TRUE) menggunakan fungsi BINOM.DIST dengan argumen C11, C12, C13, dan TRUE!
B12: Total Percobaan (C12) | C12: 15 | E12: Contoh Rumus Benar: | F12: '=BINOM.DIST(C11, C12, C13, TRUE)
B13: Peluang Sukses (C13) | C13: 0.5 | E13: Contoh Hasil Benar: | F13: =BINOM.DIST(C11, C12, C13, TRUE)
B14: Kumulatif | C14: 1
B16: 3️⃣ 5 SOAL TES DUNIA NYATA — KERJAKAN DI KOTAK KUNING (TANPA KUNCI RUMUS / HASIL DI SINI!)
B17: 📌 Catatan Tes: Soal Tes #1 s/d #5 di bawah ini tidak menampilkan kunci rumus maupun hasil. Kunci jawaban lengkap tersedia di sheet paling terakhir (99_KUNCI_JAWABAN).
B19: 📝 SOAL TES #1: Kasus Keuangan & Akuntansi Kantor
B20: Parameter Binomial | C20: Nilai Input | E20: Persoalan Tes #1: Hitung peluang distribusi kumulatif (TRUE) menggunakan fungsi BINOM.DIST dengan argumen C21, C22, C23, dan TRUE!
B21: Jumlah Sukses/Gagal (C21) | C21: 2 | E21: ✏️ KETIK RUMUS JAWABAN TES DI BAWAH: | F21: 📌 STATUS KOREKSI JAWABAN TES:
B22: Total Percobaan (C22) | C22: 10 | F22: =IF(ISBLANK(E22), "⏳ Belum Diisi (Ketik Rumus di Sel Kuning E22)", IF(E22='99_KUNCI_JAWABAN'!F40, "✅ BENAR! JAWABAN TES TEPAT!", "❌ Belum Tepat (Cek Sheet Akhir: 99_KUNCI_JAWABAN)"))
B23: Peluang Sukses (C23) | C23: 0.5
B24: Kumulatif | C24: 1
B27: 📝 SOAL TES #2: Kasus HRD, Gaji & Lembur Karyawan
B28: Parameter Binomial | C28: Nilai Input | E28: Persoalan Tes #2: Hitung peluang distribusi kumulatif (TRUE) menggunakan fungsi BINOM.DIST dengan argumen C29, C30, C31, dan TRUE!
B29: Jumlah Sukses/Gagal (C29) | C29: 3 | E29: ✏️ KETIK RUMUS JAWABAN TES DI BAWAH: | F29: 📌 STATUS KOREKSI JAWABAN TES:
B30: Total Percobaan (C30) | C30: 11 | F30: =IF(ISBLANK(E30), "⏳ Belum Diisi (Ketik Rumus di Sel Kuning E30)", IF(E30='99_KUNCI_JAWABAN'!F41, "✅ BENAR! JAWABAN TES TEPAT!", "❌ Belum Tepat (Cek Sheet Akhir: 99_KUNCI_JAWABAN)"))
B31: Peluang Sukses (C31) | C31: 0.5
B32: Kumulatif | C32: 1
B35: 📝 SOAL TES #3: Kasus Logistik & Stok Gudang Utama
B36: Parameter Binomial | C36: Nilai Input | E36: Persoalan Tes #3: Hitung peluang distribusi kumulatif (TRUE) menggunakan fungsi BINOM.DIST dengan argumen C37, C38, C39, dan TRUE!
B37: Jumlah Sukses/Gagal (C37) | C37: 4 | E37: ✏️ KETIK RUMUS JAWABAN TES DI BAWAH: | F37: 📌 STATUS KOREKSI JAWABAN TES:
B38: Total Percobaan (C38) | C38: 12 | F38: =IF(ISBLANK(E38), "⏳ Belum Diisi (Ketik Rumus di Sel Kuning E38)", IF(E38='99_KUNCI_JAWABAN'!F42, "✅ BENAR! JAWABAN TES TEPAT!", "❌ Belum Tepat (Cek Sheet Akhir: 99_KUNCI_JAWABAN)"))
B39: Peluang Sukses (C39) | C39: 0.5
B40: Kumulatif | C40: 1
B43: 📝 SOAL TES #4: Kasus Penjualan Retail & Target Toko
B44: Parameter Binomial | C44: Nilai Input | E44: Persoalan Tes #4: Hitung peluang distribusi kumulatif (TRUE) menggunakan fungsi BINOM.DIST dengan argumen C45, C46, C47, dan TRUE!
B45: Jumlah Sukses/Gagal (C45) | C45: 2 | E45: ✏️ KETIK RUMUS JAWABAN TES DI BAWAH: | F45: 📌 STATUS KOREKSI JAWABAN TES:
B46: Total Percobaan (C46) | C46: 13 | F46: =IF(ISBLANK(E46), "⏳ Belum Diisi (Ketik Rumus di Sel Kuning E46)", IF(E46='99_KUNCI_JAWABAN'!F43, "✅ BENAR! JAWABAN TES TEPAT!", "❌ Belum Tepat (Cek Sheet Akhir: 99_KUNCI_JAWABAN)"))
B47: Peluang Sukses (C47) | C47: 0.5
B48: Kumulatif | C48: 1
B51: 📝 SOAL TES #5: Kasus Akademik Sekolah & Layanan Publik
B52: Parameter Binomial | C52: Nilai Input | E52: Persoalan Tes #5: Hitung peluang distribusi kumulatif (TRUE) menggunakan fungsi BINOM.DIST dengan argumen C53, C54, C55, dan TRUE!
...

Sheet BINOM.INV
B1: 📊 #009 — RUMUS EXCEL: BINOM.INV | Kategori: 8. Statistik & Analisis Data
B2: 1 Rumus = 1 Contoh Soal + Jawaban Benar & 5 Soal Tes Mandiri (Kunci Jawaban Ada di Sheet Paling Terakhir) | F2: ⬅️ Ke Daftar Isi (00_DAFTAR_ISI) | G2: 🔑 Ke Kunci Jawaban (Sheet Akhir)
B4: 1️⃣ IDENTITAS RUMUS & FUNGSINYA BUAT APA? (BINOM.INV)
B5: Nama Rumus Excel | C5: =BINOM.INV(...)
B6: Sintaks / Pola Umum | C6: =BINOM.INV(cobaan, prob_sukses, alpha)
B7: 👶 Fungsinya Buat Apa? | C7: Mencari nilai terkecil sehingga distribusi binomial kumulatif >= alpha.
B9: 2️⃣ 1 CONTOH SOAL & CONTOH JAWABAN BENAR (PELAJARI POLA RUMUS BINOM.INV DI SINI)
B10: Parameter Binomial | C10: Nilai Input | E10: ✅ 1 CONTOH SOAL BESERTA CONTOH RUMUS & HASIL JAWABAN BENAR:
B11: Total Percobaan (C11) | C11: 20 | E11: Contoh Soal: | F11: Cari nilai batas kritis binomial menggunakan fungsi BINOM.INV dengan argumen berurutan C11, C12, dan C13!
B12: Peluang Sukses (C12) | C12: 0.5 | E12: Contoh Rumus Benar: | F12: '=BINOM.INV(C11, C12, C13)
B13: Alpha Kriteria (C13) | C13: 0.75 | E13: Contoh Hasil Benar: | F13: =BINOM.INV(C11, C12, C13)
B14: Cadangan | C14: 1
B16: 3️⃣ 5 SOAL TES DUNIA NYATA — KERJAKAN DI KOTAK KUNING (TANPA KUNCI RUMUS / HASIL DI SINI!)
B17: 📌 Catatan Tes: Soal Tes #1 s/d #5 di bawah ini tidak menampilkan kunci rumus maupun hasil. Kunci jawaban lengkap tersedia di sheet paling terakhir (99_KUNCI_JAWABAN).
B19: 📝 SOAL TES #1: Kasus Keuangan & Akuntansi Kantor
B20: Parameter Binomial | C20: Nilai Input | E20: Persoalan Tes #1: Cari nilai batas kritis binomial menggunakan fungsi BINOM.INV dengan argumen berurutan C21, C22, dan C23!
B21: Total Percobaan (C21) | C21: 10 | E21: ✏️ KETIK RUMUS JAWABAN TES DI BAWAH: | F21: 📌 STATUS KOREKSI JAWABAN TES:
B22: Peluang Sukses (C22) | C22: 0.5 | F22: =IF(ISBLANK(E22), "⏳ Belum Diisi (Ketik Rumus di Sel Kuning E22)", IF(E22='99_KUNCI_JAWABAN'!F45, "✅ BENAR! JAWABAN TES TEPAT!", "❌ Belum Tepat (Cek Sheet Akhir: 99_KUNCI_JAWABAN)"))
B23: Alpha Kriteria (C23) | C23: 0.5
B24: Cadangan | C24: 1
B27: 📝 SOAL TES #2: Kasus HRD, Gaji & Lembur Karyawan
B28: Parameter Binomial | C28: Nilai Input | E28: Persoalan Tes #2: Cari nilai batas kritis binomial menggunakan fungsi BINOM.INV dengan argumen berurutan C29, C30, dan C31!
B29: Total Percobaan (C29) | C29: 12 | E29: ✏️ KETIK RUMUS JAWABAN TES DI BAWAH: | F29: 📌 STATUS KOREKSI JAWABAN TES:
B30: Peluang Sukses (C30) | C30: 0.5 | F30: =IF(ISBLANK(E30), "⏳ Belum Diisi (Ketik Rumus di Sel Kuning E30)", IF(E30='99_KUNCI_JAWABAN'!F46, "✅ BENAR! JAWABAN TES TEPAT!", "❌ Belum Tepat (Cek Sheet Akhir: 99_KUNCI_JAWABAN)"))
B31: Alpha Kriteria (C31) | C31: 0.55
B32: Cadangan | C32: 1
B35: 📝 SOAL TES #3: Kasus Logistik & Stok Gudang Utama
B36: Parameter Binomial | C36: Nilai Input | E36: Persoalan Tes #3: Cari nilai batas kritis binomial menggunakan fungsi BINOM.INV dengan argumen berurutan C37, C38, dan C39!
B37: Total Percobaan (C37) | C37: 14 | E37: ✏️ KETIK RUMUS JAWABAN TES DI BAWAH: | F37: 📌 STATUS KOREKSI JAWABAN TES:
B38: Peluang Sukses (C38) | C38: 0.5 | F38: =IF(ISBLANK(E38), "⏳ Belum Diisi (Ketik Rumus di Sel Kuning E38)", IF(E38='99_KUNCI_JAWABAN'!F47, "✅ BENAR! JAWABAN TES TEPAT!", "❌ Belum Tepat (Cek Sheet Akhir: 99_KUNCI_JAWABAN)"))
B39: Alpha Kriteria (C39) | C39: 0.6
B40: Cadangan | C40: 1
B43: 📝 SOAL TES #4: Kasus Penjualan Retail & Target Toko
B44: Parameter Binomial | C44: Nilai Input | E44: Persoalan Tes #4: Cari nilai batas kritis binomial menggunakan fungsi BINOM.INV dengan argumen berurutan C45, C46, dan C47!
B45: Total Percobaan (C45) | C45: 16 | E45: ✏️ KETIK RUMUS JAWABAN TES DI BAWAH: | F45: 📌 STATUS KOREKSI JAWABAN TES:
B46: Peluang Sukses (C46) | C46: 0.5 | F46: =IF(ISBLANK(E46), "⏳ Belum Diisi (Ketik Rumus di Sel Kuning E46)", IF(E46='99_KUNCI_JAWABAN'!F48, "✅ BENAR! JAWABAN TES TEPAT!", "❌ Belum Tepat (Cek Sheet Akhir: 99_KUNCI_JAWABAN)"))
B47: Alpha Kriteria (C47) | C47: 0.65
B48: Cadangan | C48: 1
B51: 📝 SOAL TES #5: Kasus Akademik Sekolah & Layanan Publik
B52: Parameter Binomial | C52: Nilai Input | E52: Persoalan Tes #5: Cari nilai batas kritis binomial menggunakan fungsi BINOM.INV dengan argumen berurutan C53, C54, dan C55!
...

Sheet CHISQ.DIST
B1: 📊 #010 — RUMUS EXCEL: CHISQ.DIST | Kategori: 8. Statistik & Analisis Data
B2: 1 Rumus = 1 Contoh Soal + Jawaban Benar & 5 Soal Tes Mandiri (Kunci Jawaban Ada di Sheet Paling Terakhir) | F2: ⬅️ Ke Daftar Isi (00_DAFTAR_ISI) | G2: 🔑 Ke Kunci Jawaban (Sheet Akhir)
B4: 1️⃣ IDENTITAS RUMUS & FUNGSINYA BUAT APA? (CHISQ.DIST)
B5: Nama Rumus Excel | C5: =CHISQ.DIST(...)
B6: Sintaks / Pola Umum | C6: =CHISQ.DIST(x, deg_freedom, TRUE)
B7: 👶 Fungsinya Buat Apa? | C7: Menghasilkan distribusi probabilitas Chi-Square sisi kiri.
B9: 2️⃣ 1 CONTOH SOAL & CONTOH JAWABAN BENAR (PELAJARI POLA RUMUS CHISQ.DIST DI SINI)
B10: Nama Parameter | C10: Nilai Parameter | E10: ✅ 1 CONTOH SOAL BESERTA CONTOH RUMUS & HASIL JAWABAN BENAR:
B11: Nilai X (C11) | C11: 7 | E11: Contoh Soal: | F11: Hitung nilai distribusi kumulatif (TRUE) menggunakan fungsi CHISQ.DIST dengan argumen C11, C12, dan TRUE!
B12: Derajat / Mean (C12) | C12: 10 | E12: Contoh Rumus Benar: | F12: '=CHISQ.DIST(C11, C12, TRUE)
B13: Cadangan 1 | C13: 1 | E13: Contoh Hasil Benar: | F13: =CHISQ.DIST(C11, C12, TRUE)
B14: Cadangan 2 | C14: 1
B16: 3️⃣ 5 SOAL TES DUNIA NYATA — KERJAKAN DI KOTAK KUNING (TANPA KUNCI RUMUS / HASIL DI SINI!)
B17: 📌 Catatan Tes: Soal Tes #1 s/d #5 di bawah ini tidak menampilkan kunci rumus maupun hasil. Kunci jawaban lengkap tersedia di sheet paling terakhir (99_KUNCI_JAWABAN).
B19: 📝 SOAL TES #1: Kasus Keuangan & Akuntansi Kantor
B20: Nama Parameter | C20: Nilai Parameter | E20: Persoalan Tes #1: Hitung nilai distribusi kumulatif (TRUE) menggunakan fungsi CHISQ.DIST dengan argumen C21, C22, dan TRUE!
B21: Nilai X (C21) | C21: 2 | E21: ✏️ KETIK RUMUS JAWABAN TES DI BAWAH: | F21: 📌 STATUS KOREKSI JAWABAN TES:
B22: Derajat / Mean (C22) | C22: 5 | F22: =IF(ISBLANK(E22), "⏳ Belum Diisi (Ketik Rumus di Sel Kuning E22)", IF(E22='99_KUNCI_JAWABAN'!F50, "✅ BENAR! JAWABAN TES TEPAT!", "❌ Belum Tepat (Cek Sheet Akhir: 99_KUNCI_JAWABAN)"))
B23: Cadangan 1 | C23: 1
B24: Cadangan 2 | C24: 1
B27: 📝 SOAL TES #2: Kasus HRD, Gaji & Lembur Karyawan
B28: Nama Parameter | C28: Nilai Parameter | E28: Persoalan Tes #2: Hitung nilai distribusi kumulatif (TRUE) menggunakan fungsi CHISQ.DIST dengan argumen C29, C30, dan TRUE!
B29: Nilai X (C29) | C29: 3 | E29: ✏️ KETIK RUMUS JAWABAN TES DI BAWAH: | F29: 📌 STATUS KOREKSI JAWABAN TES:
B30: Derajat / Mean (C30) | C30: 6 | F30: =IF(ISBLANK(E30), "⏳ Belum Diisi (Ketik Rumus di Sel Kuning E30)", IF(E30='99_KUNCI_JAWABAN'!F51, "✅ BENAR! JAWABAN TES TEPAT!", "❌ Belum Tepat (Cek Sheet Akhir: 99_KUNCI_JAWABAN)"))
B31: Cadangan 1 | C31: 1
B32: Cadangan 2 | C32: 1
B35: 📝 SOAL TES #3: Kasus Logistik & Stok Gudang Utama
B36: Nama Parameter | C36: Nilai Parameter | E36: Persoalan Tes #3: Hitung nilai distribusi kumulatif (TRUE) menggunakan fungsi CHISQ.DIST dengan argumen C37, C38, dan TRUE!
B37: Nilai X (C37) | C37: 4 | E37: ✏️ KETIK RUMUS JAWABAN TES DI BAWAH: | F37: 📌 STATUS KOREKSI JAWABAN TES:
B38: Derajat / Mean (C38) | C38: 7 | F38: =IF(ISBLANK(E38), "⏳ Belum Diisi (Ketik Rumus di Sel Kuning E38)", IF(E38='99_KUNCI_JAWABAN'!F52, "✅ BENAR! JAWABAN TES TEPAT!", "❌ Belum Tepat (Cek Sheet Akhir: 99_KUNCI_JAWABAN)"))
B39: Cadangan 1 | C39: 1
B40: Cadangan 2 | C40: 1
B43: 📝 SOAL TES #4: Kasus Penjualan Retail & Target Toko
B44: Nama Parameter | C44: Nilai Parameter | E44: Persoalan Tes #4: Hitung nilai distribusi kumulatif (TRUE) menggunakan fungsi CHISQ.DIST dengan argumen C45, C46, dan TRUE!
B45: Nilai X (C45) | C45: 5 | E45: ✏️ KETIK RUMUS JAWABAN TES DI BAWAH: | F45: 📌 STATUS KOREKSI JAWABAN TES:
B46: Derajat / Mean (C46) | C46: 8 | F46: =IF(ISBLANK(E46), "⏳ Belum Diisi (Ketik Rumus di Sel Kuning E46)", IF(E46='99_KUNCI_JAWABAN'!F53, "✅ BENAR! JAWABAN TES TEPAT!", "❌ Belum Tepat (Cek Sheet Akhir: 99_KUNCI_JAWABAN)"))
B47: Cadangan 1 | C47: 1
B48: Cadangan 2 | C48: 1
B51: 📝 SOAL TES #5: Kasus Akademik Sekolah & Layanan Publik
B52: Nama Parameter | C52: Nilai Parameter | E52: Persoalan Tes #5: Hitung nilai distribusi kumulatif (TRUE) menggunakan fungsi CHISQ.DIST dengan argumen C53, C54, dan TRUE!
...

Sheet CHISQ.DIST.RT
B1: 📊 #011 — RUMUS EXCEL: CHISQ.DIST.RT | Kategori: 8. Statistik & Analisis Data
B2: 1 Rumus = 1 Contoh Soal + Jawaban Benar & 5 Soal Tes Mandiri (Kunci Jawaban Ada di Sheet Paling Terakhir) | F2: ⬅️ Ke Daftar Isi (00_DAFTAR_ISI) | G2: 🔑 Ke Kunci Jawaban (Sheet Akhir)
B4: 1️⃣ IDENTITAS RUMUS & FUNGSINYA BUAT APA? (CHISQ.DIST.RT)
B5: Nama Rumus Excel | C5: =CHISQ.DIST.RT(...)
B6: Sintaks / Pola Umum | C6: =CHISQ.DIST.RT(x, deg_freedom)
B7: 👶 Fungsinya Buat Apa? | C7: Menghasilkan probabilitas ekor kanan (Right-Tailed) dari distribusi Chi-Square.
B9: 2️⃣ 1 CONTOH SOAL & CONTOH JAWABAN BENAR (PELAJARI POLA RUMUS CHISQ.DIST.RT DI SINI)
B10: Nama Parameter | C10: Nilai Parameter | E10: ✅ 1 CONTOH SOAL BESERTA CONTOH RUMUS & HASIL JAWABAN BENAR:
B11: Nilai Uji X (C11) | C11: 3 | E11: Contoh Soal: | F11: Hitung nilai probabilitas distribusi menggunakan fungsi CHISQ.DIST.RT dengan argumen nilai X di C11 dan derajat kebebasan di C12!
B12: Derajat Kebebasan (C12) | C12: 13 | E12: Contoh Rumus Benar: | F12: '=CHISQ.DIST.RT(C11, C12)
B13: Cadangan 1 | C13: 1 | E13: Contoh Hasil Benar: | F13: =CHISQ.DIST.RT(C11, C12)
B14: Cadangan 2 | C14: 1
B16: 3️⃣ 5 SOAL TES DUNIA NYATA — KERJAKAN DI KOTAK KUNING (TANPA KUNCI RUMUS / HASIL DI SINI!)
B17: 📌 Catatan Tes: Soal Tes #1 s/d #5 di bawah ini tidak menampilkan kunci rumus maupun hasil. Kunci jawaban lengkap tersedia di sheet paling terakhir (99_KUNCI_JAWABAN).
B19: 📝 SOAL TES #1: Kasus Keuangan & Akuntansi Kantor
B20: Nama Parameter | C20: Nilai Parameter | E20: Persoalan Tes #1: Hitung nilai probabilitas distribusi menggunakan fungsi CHISQ.DIST.RT dengan argumen nilai X di C21 dan derajat kebebasan di C22!
B21: Nilai Uji X (C21) | C21: 1.5 | E21: ✏️ KETIK RUMUS JAWABAN TES DI BAWAH: | F21: 📌 STATUS KOREKSI JAWABAN TES:
B22: Derajat Kebebasan (C22) | C22: 8 | F22: =IF(ISBLANK(E22), "⏳ Belum Diisi (Ketik Rumus di Sel Kuning E22)", IF(E22='99_KUNCI_JAWABAN'!F55, "✅ BENAR! JAWABAN TES TEPAT!", "❌ Belum Tepat (Cek Sheet Akhir: 99_KUNCI_JAWABAN)"))
B23: Cadangan 1 | C23: 1
B24: Cadangan 2 | C24: 1
B27: 📝 SOAL TES #2: Kasus HRD, Gaji & Lembur Karyawan
B28: Nama Parameter | C28: Nilai Parameter | E28: Persoalan Tes #2: Hitung nilai probabilitas distribusi menggunakan fungsi CHISQ.DIST.RT dengan argumen nilai X di C29 dan derajat kebebasan di C30!
B29: Nilai Uji X (C29) | C29: 1.8 | E29: ✏️ KETIK RUMUS JAWABAN TES DI BAWAH: | F29: 📌 STATUS KOREKSI JAWABAN TES:
B30: Derajat Kebebasan (C30) | C30: 9 | F30: =IF(ISBLANK(E30), "⏳ Belum Diisi (Ketik Rumus di Sel Kuning E30)", IF(E30='99_KUNCI_JAWABAN'!F56, "✅ BENAR! JAWABAN TES TEPAT!", "❌ Belum Tepat (Cek Sheet Akhir: 99_KUNCI_JAWABAN)"))
B31: Cadangan 1 | C31: 1
B32: Cadangan 2 | C32: 1
B35: 📝 SOAL TES #3: Kasus Logistik & Stok Gudang Utama
B36: Nama Parameter | C36: Nilai Parameter | E36: Persoalan Tes #3: Hitung nilai probabilitas distribusi menggunakan fungsi CHISQ.DIST.RT dengan argumen nilai X di C37 dan derajat kebebasan di C38!
B37: Nilai Uji X (C37) | C37: 2.1 | E37: ✏️ KETIK RUMUS JAWABAN TES DI BAWAH: | F37: 📌 STATUS KOREKSI JAWABAN TES:
B38: Derajat Kebebasan (C38) | C38: 10 | F38: =IF(ISBLANK(E38), "⏳ Belum Diisi (Ketik Rumus di Sel Kuning E38)", IF(E38='99_KUNCI_JAWABAN'!F57, "✅ BENAR! JAWABAN TES TEPAT!", "❌ Belum Tepat (Cek Sheet Akhir: 99_KUNCI_JAWABAN)"))
B39: Cadangan 1 | C39: 1
B40: Cadangan 2 | C40: 1
B43: 📝 SOAL TES #4: Kasus Penjualan Retail & Target Toko
B44: Nama Parameter | C44: Nilai Parameter | E44: Persoalan Tes #4: Hitung nilai probabilitas distribusi menggunakan fungsi CHISQ.DIST.RT dengan argumen nilai X di C45 dan derajat kebebasan di C46!
B45: Nilai Uji X (C45) | C45: 2.4 | E45: ✏️ KETIK RUMUS JAWABAN TES DI BAWAH: | F45: 📌 STATUS KOREKSI JAWABAN TES:
B46: Derajat Kebebasan (C46) | C46: 11 | F46: =IF(ISBLANK(E46), "⏳ Belum Diisi (Ketik Rumus di Sel Kuning E46)", IF(E46='99_KUNCI_JAWABAN'!F58, "✅ BENAR! JAWABAN TES TEPAT!", "❌ Belum Tepat (Cek Sheet Akhir: 99_KUNCI_JAWABAN)"))
B47: Cadangan 1 | C47: 1
B48: Cadangan 2 | C48: 1
B51: 📝 SOAL TES #5: Kasus Akademik Sekolah & Layanan Publik
B52: Nama Parameter | C52: Nilai Parameter | E52: Persoalan Tes #5: Hitung nilai probabilitas distribusi menggunakan fungsi CHISQ.DIST.RT dengan argumen nilai X di C53 dan derajat kebebasan di C54!
...

Sheet CHISQ.INV
B1: 📊 #012 — RUMUS EXCEL: CHISQ.INV | Kategori: 8. Statistik & Analisis Data
B2: 1 Rumus = 1 Contoh Soal + Jawaban Benar & 5 Soal Tes Mandiri (Kunci Jawaban Ada di Sheet Paling Terakhir) | F2: ⬅️ Ke Daftar Isi (00_DAFTAR_ISI) | G2: 🔑 Ke Kunci Jawaban (Sheet Akhir)
B4: 1️⃣ IDENTITAS RUMUS & FUNGSINYA BUAT APA? (CHISQ.INV)
B5: Nama Rumus Excel | C5: =CHISQ.INV(...)
B6: Sintaks / Pola Umum | C6: =CHISQ.INV(probabilitas, deg_freedom)
B7: 👶 Fungsinya Buat Apa? | C7: Menghasilkan nilai invers probabilitas ekor kiri dari distribusi Chi-Square.
B9: 2️⃣ 1 CONTOH SOAL & CONTOH JAWABAN BENAR (PELAJARI POLA RUMUS CHISQ.INV DI SINI)
B10: Nama Parameter | C10: Nilai Parameter | E10: ✅ 1 CONTOH SOAL BESERTA CONTOH RUMUS & HASIL JAWABAN BENAR:
B11: Probabilitas (C11) | C11: 0.15 | E11: Contoh Soal: | F11: Hitung nilai invers distribusi menggunakan fungsi CHISQ.INV dengan probabilitas di C11 dan derajat kebebasan di C12!
B12: Derajat Kebebasan (C12) | C12: 13 | E12: Contoh Rumus Benar: | F12: '=CHISQ.INV(C11, C12)
B13: Cadangan 1 | C13: 1 | E13: Contoh Hasil Benar: | F13: =CHISQ.INV(C11, C12)
B14: Cadangan 2 | C14: 1
B16: 3️⃣ 5 SOAL TES DUNIA NYATA — KERJAKAN DI KOTAK KUNING (TANPA KUNCI RUMUS / HASIL DI SINI!)
B17: 📌 Catatan Tes: Soal Tes #1 s/d #5 di bawah ini tidak menampilkan kunci rumus maupun hasil. Kunci jawaban lengkap tersedia di sheet paling terakhir (99_KUNCI_JAWABAN).
B19: 📝 SOAL TES #1: Kasus Keuangan & Akuntansi Kantor
B20: Nama Parameter | C20: Nilai Parameter | E20: Persoalan Tes #1: Hitung nilai invers distribusi menggunakan fungsi CHISQ.INV dengan probabilitas di C21 dan derajat kebebasan di C22!
B21: Probabilitas (C21) | C21: 0.05 | E21: ✏️ KETIK RUMUS JAWABAN TES DI BAWAH: | F21: 📌 STATUS KOREKSI JAWABAN TES:
B22: Derajat Kebebasan (C22) | C22: 8 | F22: =IF(ISBLANK(E22), "⏳ Belum Diisi (Ketik Rumus di Sel Kuning E22)", IF(E22='99_KUNCI_JAWABAN'!F60, "✅ BENAR! JAWABAN TES TEPAT!", "❌ Belum Tepat (Cek Sheet Akhir: 99_KUNCI_JAWABAN)"))
B23: Cadangan 1 | C23: 1
B24: Cadangan 2 | C24: 1
B27: 📝 SOAL TES #2: Kasus HRD, Gaji & Lembur Karyawan
B28: Nama Parameter | C28: Nilai Parameter | E28: Persoalan Tes #2: Hitung nilai invers distribusi menggunakan fungsi CHISQ.INV dengan probabilitas di C29 dan derajat kebebasan di C30!
B29: Probabilitas (C29) | C29: 0.07 | E29: ✏️ KETIK RUMUS JAWABAN TES DI BAWAH: | F29: 📌 STATUS KOREKSI JAWABAN TES:
B30: Derajat Kebebasan (C30) | C30: 9 | F30: =IF(ISBLANK(E30), "⏳ Belum Diisi (Ketik Rumus di Sel Kuning E30)", IF(E30='99_KUNCI_JAWABAN'!F61, "✅ BENAR! JAWABAN TES TEPAT!", "❌ Belum Tepat (Cek Sheet Akhir: 99_KUNCI_JAWABAN)"))
B31: Cadangan 1 | C31: 1
B32: Cadangan 2 | C32: 1
B35: 📝 SOAL TES #3: Kasus Logistik & Stok Gudang Utama
B36: Nama Parameter | C36: Nilai Parameter | E36: Persoalan Tes #3: Hitung nilai invers distribusi menggunakan fungsi CHISQ.INV dengan probabilitas di C37 dan derajat kebebasan di C38!
B37: Probabilitas (C37) | C37: 0.09 | E37: ✏️ KETIK RUMUS JAWABAN TES DI BAWAH: | F37: 📌 STATUS KOREKSI JAWABAN TES:
B38: Derajat Kebebasan (C38) | C38: 10 | F38: =IF(ISBLANK(E38), "⏳ Belum Diisi (Ketik Rumus di Sel Kuning E38)", IF(E38='99_KUNCI_JAWABAN'!F62, "✅ BENAR! JAWABAN TES TEPAT!", "❌ Belum Tepat (Cek Sheet Akhir: 99_KUNCI_JAWABAN)"))
B39: Cadangan 1 | C39: 1
B40: Cadangan 2 | C40: 1
B43: 📝 SOAL TES #4: Kasus Penjualan Retail & Target Toko
B44: Nama Parameter | C44: Nilai Parameter | E44: Persoalan Tes #4: Hitung nilai invers distribusi menggunakan fungsi CHISQ.INV dengan probabilitas di C45 dan derajat kebebasan di C46!
B45: Probabilitas (C45) | C45: 0.11 | E45: ✏️ KETIK RUMUS JAWABAN TES DI BAWAH: | F45: 📌 STATUS KOREKSI JAWABAN TES:
B46: Derajat Kebebasan (C46) | C46: 11 | F46: =IF(ISBLANK(E46), "⏳ Belum Diisi (Ketik Rumus di Sel Kuning E46)", IF(E46='99_KUNCI_JAWABAN'!F63, "✅ BENAR! JAWABAN TES TEPAT!", "❌ Belum Tepat (Cek Sheet Akhir: 99_KUNCI_JAWABAN)"))
B47: Cadangan 1 | C47: 1
B48: Cadangan 2 | C48: 1
B51: 📝 SOAL TES #5: Kasus Akademik Sekolah & Layanan Publik
B52: Nama Parameter | C52: Nilai Parameter | E52: Persoalan Tes #5: Hitung nilai invers distribusi menggunakan fungsi CHISQ.INV dengan probabilitas di C53 dan derajat kebebasan di C54!
...

Sheet CHISQ.RT.INV
B1: 📊 #013 — RUMUS EXCEL: CHISQ.RT.INV | Kategori: 8. Statistik & Analisis Data
B2: 1 Rumus = 1 Contoh Soal + Jawaban Benar & 5 Soal Tes Mandiri (Kunci Jawaban Ada di Sheet Paling Terakhir) | F2: ⬅️ Ke Daftar Isi (00_DAFTAR_ISI) | G2: 🔑 Ke Kunci Jawaban (Sheet Akhir)
B4: 1️⃣ IDENTITAS RUMUS & FUNGSINYA BUAT APA? (CHISQ.RT.INV)
B5: Nama Rumus Excel | C5: =CHISQ.RT.INV(...)
B6: Sintaks / Pola Umum | C6: =CHISQ.INV.RT(probabilitas, deg_freedom)
B7: 👶 Fungsinya Buat Apa? | C7: Menghasilkan nilai invers probabilitas ekor kanan dari distribusi Chi-Square.
B9: 2️⃣ 1 CONTOH SOAL & CONTOH JAWABAN BENAR (PELAJARI POLA RUMUS CHISQ.RT.INV DI SINI)
B10: Nama Parameter | C10: Nilai Parameter | E10: ✅ 1 CONTOH SOAL BESERTA CONTOH RUMUS & HASIL JAWABAN BENAR:
B11: Probabilitas (C11) | C11: 0.15 | E11: Contoh Soal: | F11: Hitung nilai invers distribusi menggunakan fungsi CHISQ.INV.RT dengan probabilitas di C11 dan derajat kebebasan di C12!
B12: Derajat Kebebasan (C12) | C12: 13 | E12: Contoh Rumus Benar: | F12: '=CHISQ.INV.RT(C11, C12)
B13: Cadangan 1 | C13: 1 | E13: Contoh Hasil Benar: | F13: =CHISQ.INV.RT(C11, C12)
B14: Cadangan 2 | C14: 1
B16: 3️⃣ 5 SOAL TES DUNIA NYATA — KERJAKAN DI KOTAK KUNING (TANPA KUNCI RUMUS / HASIL DI SINI!)
B17: 📌 Catatan Tes: Soal Tes #1 s/d #5 di bawah ini tidak menampilkan kunci rumus maupun hasil. Kunci jawaban lengkap tersedia di sheet paling terakhir (99_KUNCI_JAWABAN).
B19: 📝 SOAL TES #1: Kasus Keuangan & Akuntansi Kantor
B20: Nama Parameter | C20: Nilai Parameter | E20: Persoalan Tes #1: Hitung nilai invers distribusi menggunakan fungsi CHISQ.INV.RT dengan probabilitas di C21 dan derajat kebebasan di C22!
B21: Probabilitas (C21) | C21: 0.05 | E21: ✏️ KETIK RUMUS JAWABAN TES DI BAWAH: | F21: 📌 STATUS KOREKSI JAWABAN TES:
B22: Derajat Kebebasan (C22) | C22: 8 | F22: =IF(ISBLANK(E22), "⏳ Belum Diisi (Ketik Rumus di Sel Kuning E22)", IF(E22='99_KUNCI_JAWABAN'!F65, "✅ BENAR! JAWABAN TES TEPAT!", "❌ Belum Tepat (Cek Sheet Akhir: 99_KUNCI_JAWABAN)"))
B23: Cadangan 1 | C23: 1
B24: Cadangan 2 | C24: 1
B27: 📝 SOAL TES #2: Kasus HRD, Gaji & Lembur Karyawan
B28: Nama Parameter | C28: Nilai Parameter | E28: Persoalan Tes #2: Hitung nilai invers distribusi menggunakan fungsi CHISQ.INV.RT dengan probabilitas di C29 dan derajat kebebasan di C30!
B29: Probabilitas (C29) | C29: 0.07 | E29: ✏️ KETIK RUMUS JAWABAN TES DI BAWAH: | F29: 📌 STATUS KOREKSI JAWABAN TES:
B30: Derajat Kebebasan (C30) | C30: 9 | F30: =IF(ISBLANK(E30), "⏳ Belum Diisi (Ketik Rumus di Sel Kuning E30)", IF(E30='99_KUNCI_JAWABAN'!F66, "✅ BENAR! JAWABAN TES TEPAT!", "❌ Belum Tepat (Cek Sheet Akhir: 99_KUNCI_JAWABAN)"))
B31: Cadangan 1 | C31: 1
B32: Cadangan 2 | C32: 1
