Workbook

Sheet 00_DAFTAR_ISI
A1: 📚 PAKET 2: RUMUS VLOOKUP, PENGOLAHAN TEKS & TANGGAL HRD (45 SHEET RUMUS • 1 CONTOH + 5 SOAL TES PER RUMUS)
A2: Setiap Sheet berisi: 1 Contoh Soal + Jawaban Benar, lalu 5 Soal Tes Tanpa Kunci. Kunci Jawaban Lengkap ada di Sheet Paling Terakhir (99_KUNCI_JAWABAN)! | F2: 🔑 Buka 99_KUNCI_JAWABAN
A4: No | B4: Nama Rumus (Sheet) | C4: Kategori | D4: Sintaks Umum | E4: Fungsinya Buat Apa (Bahasa Bayi & Dunia Nyata) | F4: Link Buka Sheet
A5: 1 | B5: VLOOKUP | C5: 3. Lookup & Referensi | D5: =VLOOKUP(nilai_dicari, tabel_referensi, nomor_kolom, FALSE) | E5: Mesin kasir pencari data vertikal! Mencari kode di kolom paling kiri tabel, lalu mengambil informasi pasangannya di kolom sebelah kanan. | F5: 👉 Buka Sheet VLOOKUP
A6: 2 | B6: HLOOKUP | C6: 3. Lookup & Referensi | D6: =HLOOKUP(nilai_dicari, tabel_horizontal, nomor_baris, FALSE) | E6: Sama seperti VLOOKUP tetapi mencari data secara MENDATAR (Horizontal) di baris paling atas lalu turun ke baris di bawahnya. | F6: 👉 Buka Sheet HLOOKUP
A7: 3 | B7: INDEX | C7: 3. Lookup & Referensi | D7: =INDEX(range_data, nomor_baris, [nomor_kolom]) | E7: Mengambil isi sel pada koordinat urutan baris dan kolom tertentu di dalam suatu blok tabel (seperti menunjuk kursi bioskop Baris 3!). | F7: 👉 Buka Sheet INDEX
A8: 4 | B8: MATCH | C8: 3. Lookup & Referensi | D8: =MATCH(nilai_dicari, range_satu_kolom, 0) | E8: Mencari tahu suatu data berada di URUTAN BARIS KE BERAPA di dalam sebuah daftar (menghasilkan nomor urut posisi 1, 2, 3...). | F8: 👉 Buka Sheet MATCH
A9: 5 | B9: CHOOSE | C9: 3. Lookup & Referensi | D9: =CHOOSE(nomor_pilihan, nilai1, nilai2, nilai3, ...) | E9: Memilih satu item dari daftar berdasarkan nomor urut tombol (1 = pilih nilai pertama, 2 = pilih nilai kedua, dst). | F9: 👉 Buka Sheet CHOOSE
A10: 6 | B10: ROW | C10: 3. Lookup & Referensi | D10: =ROW([referensi_sel]) | E10: Memberitahu nomor baris tempat sebuah sel berada (misal ROW(C19) menghasilkan angka 19). | F10: 👉 Buka Sheet ROW
A11: 7 | B11: COLUMN | C11: 3. Lookup & Referensi | D11: =COLUMN([referensi_sel]) | E11: Memberitahu nomor urut kolom sebuah sel (Kolom A = 1, Kolom B = 2, Kolom C = 3, dst). | F11: 👉 Buka Sheet COLUMN
A12: 8 | B12: ROWS | C12: 3. Lookup & Referensi | D12: =ROWS(range_tabel) | E12: Menghitung ada berapa total baris di dalam suatu blok tabel. | F12: 👉 Buka Sheet ROWS
A13: 9 | B13: COLUMNS | C13: 3. Lookup & Referensi | D13: =COLUMNS(range_tabel) | E13: Menghitung ada berapa total kolom menyamping di dalam suatu blok tabel. | F13: 👉 Buka Sheet COLUMNS
A14: 10 | B14: ADDRESS | C14: 3. Lookup & Referensi | D14: =ADDRESS(nomor_baris, nomor_kolom) | E14: Merakit teks alamat koordinat sel (seperti $C$19) dari angka nomor baris dan nomor kolom. | F14: 👉 Buka Sheet ADDRESS
A15: 11 | B15: OFFSET | C15: 3. Lookup & Referensi | D15: =OFFSET(sel_awal, geser_baris, geser_kolom) | E15: Mengambil data dari sel lain dengan cara melangkah/bergeser sejumlah baris ke bawah dan kolom ke samping dari titik awal. | F15: 👉 Buka Sheet OFFSET
A16: 12 | B16: INDIRECT | C16: 3. Lookup & Referensi | D16: =INDIRECT(teks_alamat_sel) | E16: Mengubah tulisan teks biasa yang berisi alamat sel menjadi rujukan sel hidup yang diambil nilainya! | F16: 👉 Buka Sheet INDIRECT
A17: 13 | B17: LEFT | C17: 4. Pengolahan Teks | D17: =LEFT(teks, jumlah_karakter) | E17: Memotong dan mengambil sejumlah huruf dari sebelah KIRI (awal kata/kode barang). | F17: 👉 Buka Sheet LEFT
A18: 14 | B18: RIGHT | C18: 4. Pengolahan Teks | D18: =RIGHT(teks, jumlah_karakter) | E18: Memotong dan mengambil sejumlah huruf dari sebelah KANAN (ujung belakang kata/kode barang). | F18: 👉 Buka Sheet RIGHT
A19: 15 | B19: MID | C19: 4. Pengolahan Teks | D19: =MID(teks, posisi_mulai, jumlah_karakter) | E19: Mengambil huruf dari bagian TENGAH teks, dimulai dari urutan huruf tertentu sebanyak beberapa karakter. | F19: 👉 Buka Sheet MID
A20: 16 | B20: LEN | C20: 4. Pengolahan Teks | D20: =LEN(teks) | E20: Menghitung total panjang karakter (jumlah huruf, angka, dan spasi) di dalam sebuah sel. Wajib untuk validasi panjang NIK 16 digit! | F20: 👉 Buka Sheet LEN
A21: 17 | B21: TRIM | C21: 4. Pengolahan Teks | D21: =TRIM(teks) | E21: Sapu pembersih spasi! Menghapus spasi ganda yang berantakan di awal, tengah, atau akhir kalimat sehingga rapi. | F21: 👉 Buka Sheet TRIM
A22: 18 | B22: CLEAN | C22: 4. Pengolahan Teks | D22: =CLEAN(teks) | E22: Membersihkan karakter aneh tak terlihat (non-printable characters) hasil copy-paste dari web atau sistem database. | F22: 👉 Buka Sheet CLEAN
A23: 19 | B23: UPPER | C23: 4. Pengolahan Teks | D23: =UPPER(teks) | E23: Mengubah seluruh huruf di dalam sel menjadi HURUF BESAR (KAPITAL) semua. | F23: 👉 Buka Sheet UPPER
A24: 20 | B24: LOWER | C24: 4. Pengolahan Teks | D24: =LOWER(teks) | E24: Mengubah seluruh huruf di dalam sel menjadi huruf kecil semua (cocok untuk merapikan alamat email). | F24: 👉 Buka Sheet LOWER
A25: 21 | B25: PROPER | C25: 4. Pengolahan Teks | D25: =PROPER(teks) | E25: Mengubah huruf pertama di setiap awal kata menjadi Huruf Besar (Title Case), sangat cocok untuk merapikan daftar Nama Lengkap! | F25: 👉 Buka Sheet PROPER
A26: 22 | B26: CONCATENATE | C26: 4. Pengolahan Teks | D26: =CONCATENATE(teks1, teks2, ...) | E26: Lem perekat teks! Menggabungkan isi dari beberapa sel terpisah (misal Nama Depan dan Nama Belakang) menjadi satu kalimat utuh. | F26: 👉 Buka Sheet CONCATENATE
A27: 23 | B27: EXACT | C27: 4. Pengolahan Teks | D27: =EXACT(teks1, teks2) | E27: Detektor kembar identik! Membandingkan apakah dua teks sama persis sampai ke huruf besar-kecilnya (Case-Sensitive). | F27: 👉 Buka Sheet EXACT
A28: 24 | B28: FIND | C28: 4. Pengolahan Teks | D28: =FIND(teks_dicari, di_dalam_teks) | E28: Mencari tahu suatu huruf atau simbol berada pada urutan karakter ke berapa (membedakan huruf besar dan kecil). | F28: 👉 Buka Sheet FIND
A29: 25 | B29: SEARCH | C29: 4. Pengolahan Teks | D29: =SEARCH(teks_dicari, di_dalam_teks) | E29: Sama seperti FIND (mencari posisi urutan huruf), tetapi TIDAK membedakan huruf besar maupun kecil! | F29: 👉 Buka Sheet SEARCH
A30: 26 | B30: SUBSTITUTE | C30: 4. Pengolahan Teks | D30: =SUBSTITUTE(teks, teks_lama, teks_baru) | E30: Mengganti kata atau simbol tertentu di dalam sel dengan kata/simbol baru secara otomatis (misal ganti tanda '-' menjadi '/'). | F30: 👉 Buka Sheet SUBSTITUTE
A31: 27 | B31: REPLACE | C31: 4. Pengolahan Teks | D31: =REPLACE(teks_lama, posisi_mulai, jumlah_diganti, teks_baru) | E31: Mengganti sebagian isi teks berdasarkan posisi nomor urut karakter dan panjang huruf yang ingin ditimpa. | F31: 👉 Buka Sheet REPLACE
A32: 28 | B32: REPT | C32: 4. Pengolahan Teks | D32: =REPT(teks, jumlah_ulang) | E32: Mengulang teks atau simbol berkali-kali (sering dipakai membuat grafik bintang ⭐⭐⭐⭐⭐ langsung di dalam sel Excel!). | F32: 👉 Buka Sheet REPT
A33: 29 | B33: VALUE | C33: 4. Pengolahan Teks | D33: =VALUE(teks_angka) | E33: Mengubah angka yang berstatus 'Teks' (biasanya rata kiri dan tidak bisa di-SUM) kembali menjadi Angka Murni yang bisa dihitung! | F33: 👉 Buka Sheet VALUE
A34: 30 | B34: TEXT | C34: 4. Pengolahan Teks | D34: =TEXT(nilai, format_tampilan) | E34: Mengubah angka atau tanggal menjadi teks dengan format tampilan cantik sesuai keinginan (misal "#,##0"). | F34: 👉 Buka Sheet TEXT
A35: 31 | B35: DATE | C35: 5. Tanggal & Waktu HRD | D35: =DATE(tahun, bulan, tanggal) | E35: Merakit 3 angka terpisah (Tahun, Bulan, Hari) menjadi satu Tanggal Resmi Excel yang valid! | F35: 👉 Buka Sheet DATE
A36: 32 | B36: YEAR | C36: 5. Tanggal & Waktu HRD | D36: =YEAR(tanggal) | E36: Mengambil angka TAHUN (4 digit, misal 2026) dari sebuah sel tanggal. | F36: 👉 Buka Sheet YEAR
A37: 33 | B37: MONTH | C37: 5. Tanggal & Waktu HRD | D37: =MONTH(tanggal) | E37: Mengambil angka BULAN (1 sampai 12) dari sebuah sel tanggal. | F37: 👉 Buka Sheet MONTH
A38: 34 | B38: DAY | C38: 5. Tanggal & Waktu HRD | D38: =DAY(tanggal) | E38: Mengambil angka HARI/TANGGAL (1 sampai 31) dari sebuah sel tanggal. | F38: 👉 Buka Sheet DAY
A39: 35 | B39: DAYS | C39: 5. Tanggal & Waktu HRD | D39: =DAYS(tanggal_akhir, tanggal_awal) | E39: Menghitung jumlah hari selisih antara Tanggal Akhir dan Tanggal Awal (misal lama keterlambatan proyek). | F39: 👉 Buka Sheet DAYS
A40: 36 | B40: DATEDIF | C40: 5. Tanggal & Waktu HRD | D40: =DATEDIF(tanggal_awal, tanggal_akhir, satuan) | E40: Rumus legendaris HRD untuk menghitung Umur atau Masa Kerja karyawan dalam Tahun ("Y"), Bulan ("M"), atau Hari ("D"). | F40: 👉 Buka Sheet DATEDIF
A41: 37 | B41: EDATE | C41: 5. Tanggal & Waktu HRD | D41: =EDATE(tanggal_awal, jumlah_bulan) | E41: Mencari tanggal jatuh tempo yang berjarak sekian bulan persis dari tanggal awal (misal masa kontrak 3 bulan ke depan). | F41: 👉 Buka Sheet EDATE
...

Sheet VLOOKUP
B1: 📊 #001 — RUMUS EXCEL: VLOOKUP | Kategori: 3. Lookup & Referensi
B2: 1 Rumus = 1 Contoh Soal + Jawaban Benar & 5 Soal Tes Mandiri (Kunci Jawaban Ada di Sheet Paling Terakhir) | F2: ⬅️ Ke Daftar Isi (00_DAFTAR_ISI) | G2: 🔑 Ke Kunci Jawaban (Sheet Akhir)
B4: 1️⃣ IDENTITAS RUMUS & FUNGSINYA BUAT APA? (VLOOKUP)
B5: Nama Rumus Excel | C5: =VLOOKUP(...)
B6: Sintaks / Pola Umum | C6: =VLOOKUP(nilai_dicari, tabel_referensi, nomor_kolom, FALSE)
B7: 👶 Fungsinya Buat Apa? | C7: Mesin kasir pencari data vertikal! Mencari kode di kolom paling kiri tabel, lalu mengambil informasi pasangannya di kolom sebelah kanan.
B9: 2️⃣ 1 CONTOH SOAL & CONTOH JAWABAN BENAR (PELAJARI POLA RUMUS VLOOKUP DI SINI)
B10: Kode Barang (Kol 1) | C10: Harga Barang (Kol 2) | E10: ✅ 1 CONTOH SOAL BESERTA CONTOH RUMUS & HASIL JAWABAN BENAR:
B11: K01 | C11: 500000 | E11: Contoh Soal: | F11: Cari harga untuk kode "K02" pada tabel referensi B11:C14 (ambil kolom ke-2 dengan pencocokan eksak FALSE) menggunakan fungsi VLOOKUP!
B12: K02 | C12: 750000 | E12: Contoh Rumus Benar: | F12: '=VLOOKUP("K02", B11:C14, 2, FALSE)
B13: K03 | C13: 600000 | E13: Contoh Hasil Benar: | F13: =VLOOKUP("K02", B11:C14, 2, FALSE)
B14: K04 | C14: 950000
B16: 3️⃣ 5 SOAL TES DUNIA NYATA — KERJAKAN DI KOTAK KUNING (TANPA KUNCI RUMUS / HASIL DI SINI!)
B17: 📌 Catatan Tes: Soal Tes #1 s/d #5 di bawah ini tidak menampilkan kunci rumus maupun hasil. Kunci jawaban lengkap tersedia di sheet paling terakhir (99_KUNCI_JAWABAN).
B19: 📝 SOAL TES #1: Kasus Keuangan & Akuntansi Kantor
B20: Kode Barang (Kol 1) | C20: Harga Barang (Kol 2) | E20: Persoalan Tes #1: Cari harga untuk kode "K01" pada tabel referensi B21:C24 (ambil kolom ke-2 dengan pencocokan eksak FALSE) menggunakan fungsi VLOOKUP!
B21: K01 | C21: 1250000 | E21: ✏️ KETIK RUMUS JAWABAN TES DI BAWAH: | F21: 📌 STATUS KOREKSI JAWABAN TES:
B22: K02 | C22: 1850000 | F22: =IF(ISBLANK(E22), "⏳ Belum Diisi (Ketik Rumus di Sel Kuning E22)", IF(E22='99_KUNCI_JAWABAN'!F5, "✅ BENAR! JAWABAN TES TEPAT!", "❌ Belum Tepat (Cek Sheet Akhir: 99_KUNCI_JAWABAN)"))
B23: K03 | C23: 2100000
B24: K04 | C24: 1600000
B27: 📝 SOAL TES #2: Kasus HRD, Gaji & Lembur Karyawan
B28: Kode Barang (Kol 1) | C28: Harga Barang (Kol 2) | E28: Persoalan Tes #2: Cari harga untuk kode "K02" pada tabel referensi B29:C32 (ambil kolom ke-2 dengan pencocokan eksak FALSE) menggunakan fungsi VLOOKUP!
B29: K01 | C29: 4500000 | E29: ✏️ KETIK RUMUS JAWABAN TES DI BAWAH: | F29: 📌 STATUS KOREKSI JAWABAN TES:
B30: K02 | C30: 5200000 | F30: =IF(ISBLANK(E30), "⏳ Belum Diisi (Ketik Rumus di Sel Kuning E30)", IF(E30='99_KUNCI_JAWABAN'!F6, "✅ BENAR! JAWABAN TES TEPAT!", "❌ Belum Tepat (Cek Sheet Akhir: 99_KUNCI_JAWABAN)"))
B31: K03 | C31: 4800000
B32: K04 | C32: 6100000
B35: 📝 SOAL TES #3: Kasus Logistik & Stok Gudang Utama
B36: Kode Barang (Kol 1) | C36: Harga Barang (Kol 2) | E36: Persoalan Tes #3: Cari harga untuk kode "K03" pada tabel referensi B37:C40 (ambil kolom ke-2 dengan pencocokan eksak FALSE) menggunakan fungsi VLOOKUP!
B37: K01 | C37: 240 | E37: ✏️ KETIK RUMUS JAWABAN TES DI BAWAH: | F37: 📌 STATUS KOREKSI JAWABAN TES:
B38: K02 | C38: 380 | F38: =IF(ISBLANK(E38), "⏳ Belum Diisi (Ketik Rumus di Sel Kuning E38)", IF(E38='99_KUNCI_JAWABAN'!F7, "✅ BENAR! JAWABAN TES TEPAT!", "❌ Belum Tepat (Cek Sheet Akhir: 99_KUNCI_JAWABAN)"))
B39: K03 | C39: 195
B40: K04 | C40: 425
B43: 📝 SOAL TES #4: Kasus Penjualan Retail & Target Toko
B44: Kode Barang (Kol 1) | C44: Harga Barang (Kol 2) | E44: Persoalan Tes #4: Cari harga untuk kode "K04" pada tabel referensi B45:C48 (ambil kolom ke-2 dengan pencocokan eksak FALSE) menggunakan fungsi VLOOKUP!
B45: K01 | C45: 85 | E45: ✏️ KETIK RUMUS JAWABAN TES DI BAWAH: | F45: 📌 STATUS KOREKSI JAWABAN TES:
B46: K02 | C46: 92 | F46: =IF(ISBLANK(E46), "⏳ Belum Diisi (Ketik Rumus di Sel Kuning E46)", IF(E46='99_KUNCI_JAWABAN'!F8, "✅ BENAR! JAWABAN TES TEPAT!", "❌ Belum Tepat (Cek Sheet Akhir: 99_KUNCI_JAWABAN)"))
B47: K03 | C47: 78
B48: K04 | C48: 95
B51: 📝 SOAL TES #5: Kasus Akademik Sekolah & Layanan Publik
B52: Kode Barang (Kol 1) | C52: Harga Barang (Kol 2) | E52: Persoalan Tes #5: Cari harga untuk kode "K01" pada tabel referensi B53:C56 (ambil kolom ke-2 dengan pencocokan eksak FALSE) menggunakan fungsi VLOOKUP!
...

Sheet HLOOKUP
B1: 📊 #002 — RUMUS EXCEL: HLOOKUP | Kategori: 3. Lookup & Referensi
B2: 1 Rumus = 1 Contoh Soal + Jawaban Benar & 5 Soal Tes Mandiri (Kunci Jawaban Ada di Sheet Paling Terakhir) | F2: ⬅️ Ke Daftar Isi (00_DAFTAR_ISI) | G2: 🔑 Ke Kunci Jawaban (Sheet Akhir)
B4: 1️⃣ IDENTITAS RUMUS & FUNGSINYA BUAT APA? (HLOOKUP)
B5: Nama Rumus Excel | C5: =HLOOKUP(...)
B6: Sintaks / Pola Umum | C6: =HLOOKUP(nilai_dicari, tabel_horizontal, nomor_baris, FALSE)
B7: 👶 Fungsinya Buat Apa? | C7: Sama seperti VLOOKUP tetapi mencari data secara MENDATAR (Horizontal) di baris paling atas lalu turun ke baris di bawahnya.
B9: 2️⃣ 1 CONTOH SOAL & CONTOH JAWABAN BENAR (PELAJARI POLA RUMUS HLOOKUP DI SINI)
B10: Baris Data | C10: Nilai Tabel | E10: ✅ 1 CONTOH SOAL BESERTA CONTOH RUMUS & HASIL JAWABAN BENAR:
B11: Simulasi Unit A | C11: 500000 | E11: Contoh Soal: | F11: Cari nilai sel C11 pada blok C11:C14 lalu ambil baris ke-2 secara eksak (FALSE) menggunakan fungsi HLOOKUP!
B12: Simulasi Unit B | C12: 750000 | E12: Contoh Rumus Benar: | F12: '=HLOOKUP(C11, C11:C14, 2, FALSE)
B13: Simulasi Unit C | C13: 600000 | E13: Contoh Hasil Benar: | F13: =HLOOKUP(C11, C11:C14, 2, FALSE)
B14: Simulasi Unit D | C14: 950000
B16: 3️⃣ 5 SOAL TES DUNIA NYATA — KERJAKAN DI KOTAK KUNING (TANPA KUNCI RUMUS / HASIL DI SINI!)
B17: 📌 Catatan Tes: Soal Tes #1 s/d #5 di bawah ini tidak menampilkan kunci rumus maupun hasil. Kunci jawaban lengkap tersedia di sheet paling terakhir (99_KUNCI_JAWABAN).
B19: 📝 SOAL TES #1: Kasus Keuangan & Akuntansi Kantor
B20: Baris Data | C20: Nilai Tabel | E20: Persoalan Tes #1: Cari nilai sel C21 pada blok C21:C24 lalu ambil baris ke-2 secara eksak (FALSE) menggunakan fungsi HLOOKUP!
B21: Cabang Jakarta | C21: 1250000 | E21: ✏️ KETIK RUMUS JAWABAN TES DI BAWAH: | F21: 📌 STATUS KOREKSI JAWABAN TES:
B22: Cabang Bandung | C22: 1850000 | F22: =IF(ISBLANK(E22), "⏳ Belum Diisi (Ketik Rumus di Sel Kuning E22)", IF(E22='99_KUNCI_JAWABAN'!F10, "✅ BENAR! JAWABAN TES TEPAT!", "❌ Belum Tepat (Cek Sheet Akhir: 99_KUNCI_JAWABAN)"))
B23: Cabang Surabaya | C23: 2100000
B24: Cabang Medan | C24: 1600000
B27: 📝 SOAL TES #2: Kasus HRD, Gaji & Lembur Karyawan
B28: Baris Data | C28: Nilai Tabel | E28: Persoalan Tes #2: Cari nilai sel C29 pada blok C29:C32 lalu ambil baris ke-2 secara eksak (FALSE) menggunakan fungsi HLOOKUP!
B29: Budi Santoso | C29: 4500000 | E29: ✏️ KETIK RUMUS JAWABAN TES DI BAWAH: | F29: 📌 STATUS KOREKSI JAWABAN TES:
B30: Siti Aminah | C30: 5200000 | F30: =IF(ISBLANK(E30), "⏳ Belum Diisi (Ketik Rumus di Sel Kuning E30)", IF(E30='99_KUNCI_JAWABAN'!F11, "✅ BENAR! JAWABAN TES TEPAT!", "❌ Belum Tepat (Cek Sheet Akhir: 99_KUNCI_JAWABAN)"))
B31: Andi Pratama | C31: 4800000
B32: Rina Wijaya | C32: 6100000
B35: 📝 SOAL TES #3: Kasus Logistik & Stok Gudang Utama
B36: Baris Data | C36: Nilai Tabel | E36: Persoalan Tes #3: Cari nilai sel C37 pada blok C37:C40 lalu ambil baris ke-2 secara eksak (FALSE) menggunakan fungsi HLOOKUP!
B37: Gudang Blok A | C37: 240 | E37: ✏️ KETIK RUMUS JAWABAN TES DI BAWAH: | F37: 📌 STATUS KOREKSI JAWABAN TES:
B38: Gudang Blok B | C38: 380 | F38: =IF(ISBLANK(E38), "⏳ Belum Diisi (Ketik Rumus di Sel Kuning E38)", IF(E38='99_KUNCI_JAWABAN'!F12, "✅ BENAR! JAWABAN TES TEPAT!", "❌ Belum Tepat (Cek Sheet Akhir: 99_KUNCI_JAWABAN)"))
B39: Gudang Blok C | C39: 195
B40: Gudang Blok D | C40: 425
B43: 📝 SOAL TES #4: Kasus Penjualan Retail & Target Toko
B44: Baris Data | C44: Nilai Tabel | E44: Persoalan Tes #4: Cari nilai sel C45 pada blok C45:C48 lalu ambil baris ke-2 secara eksak (FALSE) menggunakan fungsi HLOOKUP!
B45: Toko Elektronik | C45: 85 | E45: ✏️ KETIK RUMUS JAWABAN TES DI BAWAH: | F45: 📌 STATUS KOREKSI JAWABAN TES:
B46: Toko Komputer | C46: 92 | F46: =IF(ISBLANK(E46), "⏳ Belum Diisi (Ketik Rumus di Sel Kuning E46)", IF(E46='99_KUNCI_JAWABAN'!F13, "✅ BENAR! JAWABAN TES TEPAT!", "❌ Belum Tepat (Cek Sheet Akhir: 99_KUNCI_JAWABAN)"))
B47: Toko Aksesoris | C47: 78
B48: Toko Servis | C48: 95
B51: 📝 SOAL TES #5: Kasus Akademik Sekolah & Layanan Publik
B52: Baris Data | C52: Nilai Tabel | E52: Persoalan Tes #5: Cari nilai sel C53 pada blok C53:C56 lalu ambil baris ke-2 secara eksak (FALSE) menggunakan fungsi HLOOKUP!
...

Sheet INDEX
B1: 📊 #003 — RUMUS EXCEL: INDEX | Kategori: 3. Lookup & Referensi
B2: 1 Rumus = 1 Contoh Soal + Jawaban Benar & 5 Soal Tes Mandiri (Kunci Jawaban Ada di Sheet Paling Terakhir) | F2: ⬅️ Ke Daftar Isi (00_DAFTAR_ISI) | G2: 🔑 Ke Kunci Jawaban (Sheet Akhir)
B4: 1️⃣ IDENTITAS RUMUS & FUNGSINYA BUAT APA? (INDEX)
B5: Nama Rumus Excel | C5: =INDEX(...)
B6: Sintaks / Pola Umum | C6: =INDEX(range_data, nomor_baris, [nomor_kolom])
B7: 👶 Fungsinya Buat Apa? | C7: Mengambil isi sel pada koordinat urutan baris dan kolom tertentu di dalam suatu blok tabel (seperti menunjuk kursi bioskop Baris 3!).
B9: 2️⃣ 1 CONTOH SOAL & CONTOH JAWABAN BENAR (PELAJARI POLA RUMUS INDEX DI SINI)
B10: Nama Item | C10: Data Nilai | E10: ✅ 1 CONTOH SOAL BESERTA CONTOH RUMUS & HASIL JAWABAN BENAR:
B11: Simulasi Unit A | C11: 500000 | E11: Contoh Soal: | F11: Ambil data yang berada pada urutan baris ke-2 dari rentang C11:C14 menggunakan fungsi INDEX!
B12: Simulasi Unit B | C12: 750000 | E12: Contoh Rumus Benar: | F12: '=INDEX(C11:C14, 2)
B13: Simulasi Unit C | C13: 600000 | E13: Contoh Hasil Benar: | F13: =INDEX(C11:C14, 2)
B14: Simulasi Unit D | C14: 950000
B16: 3️⃣ 5 SOAL TES DUNIA NYATA — KERJAKAN DI KOTAK KUNING (TANPA KUNCI RUMUS / HASIL DI SINI!)
B17: 📌 Catatan Tes: Soal Tes #1 s/d #5 di bawah ini tidak menampilkan kunci rumus maupun hasil. Kunci jawaban lengkap tersedia di sheet paling terakhir (99_KUNCI_JAWABAN).
B19: 📝 SOAL TES #1: Kasus Keuangan & Akuntansi Kantor
B20: Nama Item | C20: Data Nilai | E20: Persoalan Tes #1: Ambil data yang berada pada urutan baris ke-1 dari rentang C21:C24 menggunakan fungsi INDEX!
B21: Cabang Jakarta | C21: 1250000 | E21: ✏️ KETIK RUMUS JAWABAN TES DI BAWAH: | F21: 📌 STATUS KOREKSI JAWABAN TES:
B22: Cabang Bandung | C22: 1850000 | F22: =IF(ISBLANK(E22), "⏳ Belum Diisi (Ketik Rumus di Sel Kuning E22)", IF(E22='99_KUNCI_JAWABAN'!F15, "✅ BENAR! JAWABAN TES TEPAT!", "❌ Belum Tepat (Cek Sheet Akhir: 99_KUNCI_JAWABAN)"))
B23: Cabang Surabaya | C23: 2100000
B24: Cabang Medan | C24: 1600000
B27: 📝 SOAL TES #2: Kasus HRD, Gaji & Lembur Karyawan
B28: Nama Item | C28: Data Nilai | E28: Persoalan Tes #2: Ambil data yang berada pada urutan baris ke-2 dari rentang C29:C32 menggunakan fungsi INDEX!
B29: Budi Santoso | C29: 4500000 | E29: ✏️ KETIK RUMUS JAWABAN TES DI BAWAH: | F29: 📌 STATUS KOREKSI JAWABAN TES:
B30: Siti Aminah | C30: 5200000 | F30: =IF(ISBLANK(E30), "⏳ Belum Diisi (Ketik Rumus di Sel Kuning E30)", IF(E30='99_KUNCI_JAWABAN'!F16, "✅ BENAR! JAWABAN TES TEPAT!", "❌ Belum Tepat (Cek Sheet Akhir: 99_KUNCI_JAWABAN)"))
B31: Andi Pratama | C31: 4800000
B32: Rina Wijaya | C32: 6100000
B35: 📝 SOAL TES #3: Kasus Logistik & Stok Gudang Utama
B36: Nama Item | C36: Data Nilai | E36: Persoalan Tes #3: Ambil data yang berada pada urutan baris ke-3 dari rentang C37:C40 menggunakan fungsi INDEX!
B37: Gudang Blok A | C37: 240 | E37: ✏️ KETIK RUMUS JAWABAN TES DI BAWAH: | F37: 📌 STATUS KOREKSI JAWABAN TES:
B38: Gudang Blok B | C38: 380 | F38: =IF(ISBLANK(E38), "⏳ Belum Diisi (Ketik Rumus di Sel Kuning E38)", IF(E38='99_KUNCI_JAWABAN'!F17, "✅ BENAR! JAWABAN TES TEPAT!", "❌ Belum Tepat (Cek Sheet Akhir: 99_KUNCI_JAWABAN)"))
B39: Gudang Blok C | C39: 195
B40: Gudang Blok D | C40: 425
B43: 📝 SOAL TES #4: Kasus Penjualan Retail & Target Toko
B44: Nama Item | C44: Data Nilai | E44: Persoalan Tes #4: Ambil data yang berada pada urutan baris ke-4 dari rentang C45:C48 menggunakan fungsi INDEX!
B45: Toko Elektronik | C45: 85 | E45: ✏️ KETIK RUMUS JAWABAN TES DI BAWAH: | F45: 📌 STATUS KOREKSI JAWABAN TES:
B46: Toko Komputer | C46: 92 | F46: =IF(ISBLANK(E46), "⏳ Belum Diisi (Ketik Rumus di Sel Kuning E46)", IF(E46='99_KUNCI_JAWABAN'!F18, "✅ BENAR! JAWABAN TES TEPAT!", "❌ Belum Tepat (Cek Sheet Akhir: 99_KUNCI_JAWABAN)"))
B47: Toko Aksesoris | C47: 78
B48: Toko Servis | C48: 95
B51: 📝 SOAL TES #5: Kasus Akademik Sekolah & Layanan Publik
B52: Nama Item | C52: Data Nilai | E52: Persoalan Tes #5: Ambil data yang berada pada urutan baris ke-1 dari rentang C53:C56 menggunakan fungsi INDEX!
...

Sheet MATCH
B1: 📊 #004 — RUMUS EXCEL: MATCH | Kategori: 3. Lookup & Referensi
B2: 1 Rumus = 1 Contoh Soal + Jawaban Benar & 5 Soal Tes Mandiri (Kunci Jawaban Ada di Sheet Paling Terakhir) | F2: ⬅️ Ke Daftar Isi (00_DAFTAR_ISI) | G2: 🔑 Ke Kunci Jawaban (Sheet Akhir)
B4: 1️⃣ IDENTITAS RUMUS & FUNGSINYA BUAT APA? (MATCH)
B5: Nama Rumus Excel | C5: =MATCH(...)
B6: Sintaks / Pola Umum | C6: =MATCH(nilai_dicari, range_satu_kolom, 0)
B7: 👶 Fungsinya Buat Apa? | C7: Mencari tahu suatu data berada di URUTAN BARIS KE BERAPA di dalam sebuah daftar (menghasilkan nomor urut posisi 1, 2, 3...).
B9: 2️⃣ 1 CONTOH SOAL & CONTOH JAWABAN BENAR (PELAJARI POLA RUMUS MATCH DI SINI)
B10: Daftar Nama | C10: Skor | E10: ✅ 1 CONTOH SOAL BESERTA CONTOH RUMUS & HASIL JAWABAN BENAR:
B11: Simulasi Unit A | C11: 500000 | E11: Contoh Soal: | F11: Temukan nomor urut baris dari teks "Simulasi Unit B" di dalam rentang B11:B14 (tipe pencocokan eksak 0) menggunakan fungsi MATCH!
B12: Simulasi Unit B | C12: 750000 | E12: Contoh Rumus Benar: | F12: '=MATCH("Simulasi Unit B", B11:B14, 0)
B13: Simulasi Unit C | C13: 600000 | E13: Contoh Hasil Benar: | F13: =MATCH("Simulasi Unit B", B11:B14, 0)
B14: Simulasi Unit D | C14: 950000
B16: 3️⃣ 5 SOAL TES DUNIA NYATA — KERJAKAN DI KOTAK KUNING (TANPA KUNCI RUMUS / HASIL DI SINI!)
B17: 📌 Catatan Tes: Soal Tes #1 s/d #5 di bawah ini tidak menampilkan kunci rumus maupun hasil. Kunci jawaban lengkap tersedia di sheet paling terakhir (99_KUNCI_JAWABAN).
B19: 📝 SOAL TES #1: Kasus Keuangan & Akuntansi Kantor
B20: Daftar Nama | C20: Skor | E20: Persoalan Tes #1: Temukan nomor urut baris dari teks "Cabang Jakarta" di dalam rentang B21:B24 (tipe pencocokan eksak 0) menggunakan fungsi MATCH!
B21: Cabang Jakarta | C21: 1250000 | E21: ✏️ KETIK RUMUS JAWABAN TES DI BAWAH: | F21: 📌 STATUS KOREKSI JAWABAN TES:
B22: Cabang Bandung | C22: 1850000 | F22: =IF(ISBLANK(E22), "⏳ Belum Diisi (Ketik Rumus di Sel Kuning E22)", IF(E22='99_KUNCI_JAWABAN'!F20, "✅ BENAR! JAWABAN TES TEPAT!", "❌ Belum Tepat (Cek Sheet Akhir: 99_KUNCI_JAWABAN)"))
B23: Cabang Surabaya | C23: 2100000
B24: Cabang Medan | C24: 1600000
B27: 📝 SOAL TES #2: Kasus HRD, Gaji & Lembur Karyawan
B28: Daftar Nama | C28: Skor | E28: Persoalan Tes #2: Temukan nomor urut baris dari teks "Siti Aminah" di dalam rentang B29:B32 (tipe pencocokan eksak 0) menggunakan fungsi MATCH!
B29: Budi Santoso | C29: 4500000 | E29: ✏️ KETIK RUMUS JAWABAN TES DI BAWAH: | F29: 📌 STATUS KOREKSI JAWABAN TES:
B30: Siti Aminah | C30: 5200000 | F30: =IF(ISBLANK(E30), "⏳ Belum Diisi (Ketik Rumus di Sel Kuning E30)", IF(E30='99_KUNCI_JAWABAN'!F21, "✅ BENAR! JAWABAN TES TEPAT!", "❌ Belum Tepat (Cek Sheet Akhir: 99_KUNCI_JAWABAN)"))
B31: Andi Pratama | C31: 4800000
B32: Rina Wijaya | C32: 6100000
B35: 📝 SOAL TES #3: Kasus Logistik & Stok Gudang Utama
B36: Daftar Nama | C36: Skor | E36: Persoalan Tes #3: Temukan nomor urut baris dari teks "Gudang Blok C" di dalam rentang B37:B40 (tipe pencocokan eksak 0) menggunakan fungsi MATCH!
B37: Gudang Blok A | C37: 240 | E37: ✏️ KETIK RUMUS JAWABAN TES DI BAWAH: | F37: 📌 STATUS KOREKSI JAWABAN TES:
B38: Gudang Blok B | C38: 380 | F38: =IF(ISBLANK(E38), "⏳ Belum Diisi (Ketik Rumus di Sel Kuning E38)", IF(E38='99_KUNCI_JAWABAN'!F22, "✅ BENAR! JAWABAN TES TEPAT!", "❌ Belum Tepat (Cek Sheet Akhir: 99_KUNCI_JAWABAN)"))
B39: Gudang Blok C | C39: 195
B40: Gudang Blok D | C40: 425
B43: 📝 SOAL TES #4: Kasus Penjualan Retail & Target Toko
B44: Daftar Nama | C44: Skor | E44: Persoalan Tes #4: Temukan nomor urut baris dari teks "Toko Servis" di dalam rentang B45:B48 (tipe pencocokan eksak 0) menggunakan fungsi MATCH!
B45: Toko Elektronik | C45: 85 | E45: ✏️ KETIK RUMUS JAWABAN TES DI BAWAH: | F45: 📌 STATUS KOREKSI JAWABAN TES:
B46: Toko Komputer | C46: 92 | F46: =IF(ISBLANK(E46), "⏳ Belum Diisi (Ketik Rumus di Sel Kuning E46)", IF(E46='99_KUNCI_JAWABAN'!F23, "✅ BENAR! JAWABAN TES TEPAT!", "❌ Belum Tepat (Cek Sheet Akhir: 99_KUNCI_JAWABAN)"))
B47: Toko Aksesoris | C47: 78
B48: Toko Servis | C48: 95
B51: 📝 SOAL TES #5: Kasus Akademik Sekolah & Layanan Publik
B52: Daftar Nama | C52: Skor | E52: Persoalan Tes #5: Temukan nomor urut baris dari teks "Kelas 10 IPA" di dalam rentang B53:B56 (tipe pencocokan eksak 0) menggunakan fungsi MATCH!
...

Sheet CHOOSE
B1: 📊 #005 — RUMUS EXCEL: CHOOSE | Kategori: 3. Lookup & Referensi
B2: 1 Rumus = 1 Contoh Soal + Jawaban Benar & 5 Soal Tes Mandiri (Kunci Jawaban Ada di Sheet Paling Terakhir) | F2: ⬅️ Ke Daftar Isi (00_DAFTAR_ISI) | G2: 🔑 Ke Kunci Jawaban (Sheet Akhir)
B4: 1️⃣ IDENTITAS RUMUS & FUNGSINYA BUAT APA? (CHOOSE)
B5: Nama Rumus Excel | C5: =CHOOSE(...)
B6: Sintaks / Pola Umum | C6: =CHOOSE(nomor_pilihan, nilai1, nilai2, nilai3, ...)
B7: 👶 Fungsinya Buat Apa? | C7: Memilih satu item dari daftar berdasarkan nomor urut tombol (1 = pilih nilai pertama, 2 = pilih nilai kedua, dst).
B9: 2️⃣ 1 CONTOH SOAL & CONTOH JAWABAN BENAR (PELAJARI POLA RUMUS CHOOSE DI SINI)
B10: Opsi Paket | C10: Nilai Paket | E10: ✅ 1 CONTOH SOAL BESERTA CONTOH RUMUS & HASIL JAWABAN BENAR:
B11: Simulasi Unit A | C11: 500000 | E11: Contoh Soal: | F11: Pilih opsi urutan ke-3 dari tiga kandidat sel berurutan C11, C12, dan C13 menggunakan fungsi CHOOSE!
B12: Simulasi Unit B | C12: 750000 | E12: Contoh Rumus Benar: | F12: '=CHOOSE(3, C11, C12, C13)
B13: Simulasi Unit C | C13: 600000 | E13: Contoh Hasil Benar: | F13: =CHOOSE(3, C11, C12, C13)
B14: Simulasi Unit D | C14: 950000
B16: 3️⃣ 5 SOAL TES DUNIA NYATA — KERJAKAN DI KOTAK KUNING (TANPA KUNCI RUMUS / HASIL DI SINI!)
B17: 📌 Catatan Tes: Soal Tes #1 s/d #5 di bawah ini tidak menampilkan kunci rumus maupun hasil. Kunci jawaban lengkap tersedia di sheet paling terakhir (99_KUNCI_JAWABAN).
B19: 📝 SOAL TES #1: Kasus Keuangan & Akuntansi Kantor
B20: Opsi Paket | C20: Nilai Paket | E20: Persoalan Tes #1: Pilih opsi urutan ke-1 dari tiga kandidat sel berurutan C21, C22, dan C23 menggunakan fungsi CHOOSE!
B21: Cabang Jakarta | C21: 1250000 | E21: ✏️ KETIK RUMUS JAWABAN TES DI BAWAH: | F21: 📌 STATUS KOREKSI JAWABAN TES:
B22: Cabang Bandung | C22: 1850000 | F22: =IF(ISBLANK(E22), "⏳ Belum Diisi (Ketik Rumus di Sel Kuning E22)", IF(E22='99_KUNCI_JAWABAN'!F25, "✅ BENAR! JAWABAN TES TEPAT!", "❌ Belum Tepat (Cek Sheet Akhir: 99_KUNCI_JAWABAN)"))
B23: Cabang Surabaya | C23: 2100000
B24: Cabang Medan | C24: 1600000
B27: 📝 SOAL TES #2: Kasus HRD, Gaji & Lembur Karyawan
B28: Opsi Paket | C28: Nilai Paket | E28: Persoalan Tes #2: Pilih opsi urutan ke-2 dari tiga kandidat sel berurutan C29, C30, dan C31 menggunakan fungsi CHOOSE!
B29: Budi Santoso | C29: 4500000 | E29: ✏️ KETIK RUMUS JAWABAN TES DI BAWAH: | F29: 📌 STATUS KOREKSI JAWABAN TES:
B30: Siti Aminah | C30: 5200000 | F30: =IF(ISBLANK(E30), "⏳ Belum Diisi (Ketik Rumus di Sel Kuning E30)", IF(E30='99_KUNCI_JAWABAN'!F26, "✅ BENAR! JAWABAN TES TEPAT!", "❌ Belum Tepat (Cek Sheet Akhir: 99_KUNCI_JAWABAN)"))
B31: Andi Pratama | C31: 4800000
B32: Rina Wijaya | C32: 6100000
B35: 📝 SOAL TES #3: Kasus Logistik & Stok Gudang Utama
B36: Opsi Paket | C36: Nilai Paket | E36: Persoalan Tes #3: Pilih opsi urutan ke-3 dari tiga kandidat sel berurutan C37, C38, dan C39 menggunakan fungsi CHOOSE!
B37: Gudang Blok A | C37: 240 | E37: ✏️ KETIK RUMUS JAWABAN TES DI BAWAH: | F37: 📌 STATUS KOREKSI JAWABAN TES:
B38: Gudang Blok B | C38: 380 | F38: =IF(ISBLANK(E38), "⏳ Belum Diisi (Ketik Rumus di Sel Kuning E38)", IF(E38='99_KUNCI_JAWABAN'!F27, "✅ BENAR! JAWABAN TES TEPAT!", "❌ Belum Tepat (Cek Sheet Akhir: 99_KUNCI_JAWABAN)"))
B39: Gudang Blok C | C39: 195
B40: Gudang Blok D | C40: 425
B43: 📝 SOAL TES #4: Kasus Penjualan Retail & Target Toko
B44: Opsi Paket | C44: Nilai Paket | E44: Persoalan Tes #4: Pilih opsi urutan ke-1 dari tiga kandidat sel berurutan C45, C46, dan C47 menggunakan fungsi CHOOSE!
B45: Toko Elektronik | C45: 85 | E45: ✏️ KETIK RUMUS JAWABAN TES DI BAWAH: | F45: 📌 STATUS KOREKSI JAWABAN TES:
B46: Toko Komputer | C46: 92 | F46: =IF(ISBLANK(E46), "⏳ Belum Diisi (Ketik Rumus di Sel Kuning E46)", IF(E46='99_KUNCI_JAWABAN'!F28, "✅ BENAR! JAWABAN TES TEPAT!", "❌ Belum Tepat (Cek Sheet Akhir: 99_KUNCI_JAWABAN)"))
B47: Toko Aksesoris | C47: 78
B48: Toko Servis | C48: 95
B51: 📝 SOAL TES #5: Kasus Akademik Sekolah & Layanan Publik
B52: Opsi Paket | C52: Nilai Paket | E52: Persoalan Tes #5: Pilih opsi urutan ke-2 dari tiga kandidat sel berurutan C53, C54, dan C55 menggunakan fungsi CHOOSE!
...

Sheet ROW
B1: 📊 #006 — RUMUS EXCEL: ROW | Kategori: 3. Lookup & Referensi
B2: 1 Rumus = 1 Contoh Soal + Jawaban Benar & 5 Soal Tes Mandiri (Kunci Jawaban Ada di Sheet Paling Terakhir) | F2: ⬅️ Ke Daftar Isi (00_DAFTAR_ISI) | G2: 🔑 Ke Kunci Jawaban (Sheet Akhir)
B4: 1️⃣ IDENTITAS RUMUS & FUNGSINYA BUAT APA? (ROW)
B5: Nama Rumus Excel | C5: =ROW(...)
B6: Sintaks / Pola Umum | C6: =ROW([referensi_sel])
B7: 👶 Fungsinya Buat Apa? | C7: Memberitahu nomor baris tempat sebuah sel berada (misal ROW(C19) menghasilkan angka 19).
B9: 2️⃣ 1 CONTOH SOAL & CONTOH JAWABAN BENAR (PELAJARI POLA RUMUS ROW DI SINI)
B10: Label | C10: Data | E10: ✅ 1 CONTOH SOAL BESERTA CONTOH RUMUS & HASIL JAWABAN BENAR:
B11: Simulasi Unit A | C11: 500000 | E11: Contoh Soal: | F11: Periksa nomor urut posisi sel C11 menggunakan fungsi referensi ROW!
B12: Simulasi Unit B | C12: 750000 | E12: Contoh Rumus Benar: | F12: '=ROW(C11)
B13: Simulasi Unit C | C13: 600000 | E13: Contoh Hasil Benar: | F13: =ROW(C11)
B14: Simulasi Unit D | C14: 950000
B16: 3️⃣ 5 SOAL TES DUNIA NYATA — KERJAKAN DI KOTAK KUNING (TANPA KUNCI RUMUS / HASIL DI SINI!)
B17: 📌 Catatan Tes: Soal Tes #1 s/d #5 di bawah ini tidak menampilkan kunci rumus maupun hasil. Kunci jawaban lengkap tersedia di sheet paling terakhir (99_KUNCI_JAWABAN).
B19: 📝 SOAL TES #1: Kasus Keuangan & Akuntansi Kantor
B20: Label | C20: Data | E20: Persoalan Tes #1: Periksa nomor urut posisi sel C21 menggunakan fungsi referensi ROW!
B21: Cabang Jakarta | C21: 1250000 | E21: ✏️ KETIK RUMUS JAWABAN TES DI BAWAH: | F21: 📌 STATUS KOREKSI JAWABAN TES:
B22: Cabang Bandung | C22: 1850000 | F22: =IF(ISBLANK(E22), "⏳ Belum Diisi (Ketik Rumus di Sel Kuning E22)", IF(E22='99_KUNCI_JAWABAN'!F30, "✅ BENAR! JAWABAN TES TEPAT!", "❌ Belum Tepat (Cek Sheet Akhir: 99_KUNCI_JAWABAN)"))
B23: Cabang Surabaya | C23: 2100000
B24: Cabang Medan | C24: 1600000
B27: 📝 SOAL TES #2: Kasus HRD, Gaji & Lembur Karyawan
B28: Label | C28: Data | E28: Persoalan Tes #2: Periksa nomor urut posisi sel C29 menggunakan fungsi referensi ROW!
B29: Budi Santoso | C29: 4500000 | E29: ✏️ KETIK RUMUS JAWABAN TES DI BAWAH: | F29: 📌 STATUS KOREKSI JAWABAN TES:
B30: Siti Aminah | C30: 5200000 | F30: =IF(ISBLANK(E30), "⏳ Belum Diisi (Ketik Rumus di Sel Kuning E30)", IF(E30='99_KUNCI_JAWABAN'!F31, "✅ BENAR! JAWABAN TES TEPAT!", "❌ Belum Tepat (Cek Sheet Akhir: 99_KUNCI_JAWABAN)"))
B31: Andi Pratama | C31: 4800000
B32: Rina Wijaya | C32: 6100000
B35: 📝 SOAL TES #3: Kasus Logistik & Stok Gudang Utama
B36: Label | C36: Data | E36: Persoalan Tes #3: Periksa nomor urut posisi sel C37 menggunakan fungsi referensi ROW!
B37: Gudang Blok A | C37: 240 | E37: ✏️ KETIK RUMUS JAWABAN TES DI BAWAH: | F37: 📌 STATUS KOREKSI JAWABAN TES:
B38: Gudang Blok B | C38: 380 | F38: =IF(ISBLANK(E38), "⏳ Belum Diisi (Ketik Rumus di Sel Kuning E38)", IF(E38='99_KUNCI_JAWABAN'!F32, "✅ BENAR! JAWABAN TES TEPAT!", "❌ Belum Tepat (Cek Sheet Akhir: 99_KUNCI_JAWABAN)"))
B39: Gudang Blok C | C39: 195
B40: Gudang Blok D | C40: 425
B43: 📝 SOAL TES #4: Kasus Penjualan Retail & Target Toko
B44: Label | C44: Data | E44: Persoalan Tes #4: Periksa nomor urut posisi sel C45 menggunakan fungsi referensi ROW!
B45: Toko Elektronik | C45: 85 | E45: ✏️ KETIK RUMUS JAWABAN TES DI BAWAH: | F45: 📌 STATUS KOREKSI JAWABAN TES:
B46: Toko Komputer | C46: 92 | F46: =IF(ISBLANK(E46), "⏳ Belum Diisi (Ketik Rumus di Sel Kuning E46)", IF(E46='99_KUNCI_JAWABAN'!F33, "✅ BENAR! JAWABAN TES TEPAT!", "❌ Belum Tepat (Cek Sheet Akhir: 99_KUNCI_JAWABAN)"))
B47: Toko Aksesoris | C47: 78
B48: Toko Servis | C48: 95
B51: 📝 SOAL TES #5: Kasus Akademik Sekolah & Layanan Publik
B52: Label | C52: Data | E52: Persoalan Tes #5: Periksa nomor urut posisi sel C53 menggunakan fungsi referensi ROW!
...

Sheet COLUMN
B1: 📊 #007 — RUMUS EXCEL: COLUMN | Kategori: 3. Lookup & Referensi
B2: 1 Rumus = 1 Contoh Soal + Jawaban Benar & 5 Soal Tes Mandiri (Kunci Jawaban Ada di Sheet Paling Terakhir) | F2: ⬅️ Ke Daftar Isi (00_DAFTAR_ISI) | G2: 🔑 Ke Kunci Jawaban (Sheet Akhir)
B4: 1️⃣ IDENTITAS RUMUS & FUNGSINYA BUAT APA? (COLUMN)
B5: Nama Rumus Excel | C5: =COLUMN(...)
B6: Sintaks / Pola Umum | C6: =COLUMN([referensi_sel])
B7: 👶 Fungsinya Buat Apa? | C7: Memberitahu nomor urut kolom sebuah sel (Kolom A = 1, Kolom B = 2, Kolom C = 3, dst).
B9: 2️⃣ 1 CONTOH SOAL & CONTOH JAWABAN BENAR (PELAJARI POLA RUMUS COLUMN DI SINI)
B10: Label | C10: Data | E10: ✅ 1 CONTOH SOAL BESERTA CONTOH RUMUS & HASIL JAWABAN BENAR:
B11: Simulasi Unit A | C11: 500000 | E11: Contoh Soal: | F11: Periksa nomor urut posisi sel C11 menggunakan fungsi referensi COLUMN!
B12: Simulasi Unit B | C12: 750000 | E12: Contoh Rumus Benar: | F12: '=COLUMN(C11)
B13: Simulasi Unit C | C13: 600000 | E13: Contoh Hasil Benar: | F13: =COLUMN(C11)
B14: Simulasi Unit D | C14: 950000
B16: 3️⃣ 5 SOAL TES DUNIA NYATA — KERJAKAN DI KOTAK KUNING (TANPA KUNCI RUMUS / HASIL DI SINI!)
B17: 📌 Catatan Tes: Soal Tes #1 s/d #5 di bawah ini tidak menampilkan kunci rumus maupun hasil. Kunci jawaban lengkap tersedia di sheet paling terakhir (99_KUNCI_JAWABAN).
B19: 📝 SOAL TES #1: Kasus Keuangan & Akuntansi Kantor
B20: Label | C20: Data | E20: Persoalan Tes #1: Periksa nomor urut posisi sel C21 menggunakan fungsi referensi COLUMN!
B21: Cabang Jakarta | C21: 1250000 | E21: ✏️ KETIK RUMUS JAWABAN TES DI BAWAH: | F21: 📌 STATUS KOREKSI JAWABAN TES:
B22: Cabang Bandung | C22: 1850000 | F22: =IF(ISBLANK(E22), "⏳ Belum Diisi (Ketik Rumus di Sel Kuning E22)", IF(E22='99_KUNCI_JAWABAN'!F35, "✅ BENAR! JAWABAN TES TEPAT!", "❌ Belum Tepat (Cek Sheet Akhir: 99_KUNCI_JAWABAN)"))
B23: Cabang Surabaya | C23: 2100000
B24: Cabang Medan | C24: 1600000
B27: 📝 SOAL TES #2: Kasus HRD, Gaji & Lembur Karyawan
B28: Label | C28: Data | E28: Persoalan Tes #2: Periksa nomor urut posisi sel C29 menggunakan fungsi referensi COLUMN!
B29: Budi Santoso | C29: 4500000 | E29: ✏️ KETIK RUMUS JAWABAN TES DI BAWAH: | F29: 📌 STATUS KOREKSI JAWABAN TES:
B30: Siti Aminah | C30: 5200000 | F30: =IF(ISBLANK(E30), "⏳ Belum Diisi (Ketik Rumus di Sel Kuning E30)", IF(E30='99_KUNCI_JAWABAN'!F36, "✅ BENAR! JAWABAN TES TEPAT!", "❌ Belum Tepat (Cek Sheet Akhir: 99_KUNCI_JAWABAN)"))
B31: Andi Pratama | C31: 4800000
B32: Rina Wijaya | C32: 6100000
B35: 📝 SOAL TES #3: Kasus Logistik & Stok Gudang Utama
B36: Label | C36: Data | E36: Persoalan Tes #3: Periksa nomor urut posisi sel C37 menggunakan fungsi referensi COLUMN!
B37: Gudang Blok A | C37: 240 | E37: ✏️ KETIK RUMUS JAWABAN TES DI BAWAH: | F37: 📌 STATUS KOREKSI JAWABAN TES:
B38: Gudang Blok B | C38: 380 | F38: =IF(ISBLANK(E38), "⏳ Belum Diisi (Ketik Rumus di Sel Kuning E38)", IF(E38='99_KUNCI_JAWABAN'!F37, "✅ BENAR! JAWABAN TES TEPAT!", "❌ Belum Tepat (Cek Sheet Akhir: 99_KUNCI_JAWABAN)"))
B39: Gudang Blok C | C39: 195
B40: Gudang Blok D | C40: 425
B43: 📝 SOAL TES #4: Kasus Penjualan Retail & Target Toko
B44: Label | C44: Data | E44: Persoalan Tes #4: Periksa nomor urut posisi sel C45 menggunakan fungsi referensi COLUMN!
B45: Toko Elektronik | C45: 85 | E45: ✏️ KETIK RUMUS JAWABAN TES DI BAWAH: | F45: 📌 STATUS KOREKSI JAWABAN TES:
B46: Toko Komputer | C46: 92 | F46: =IF(ISBLANK(E46), "⏳ Belum Diisi (Ketik Rumus di Sel Kuning E46)", IF(E46='99_KUNCI_JAWABAN'!F38, "✅ BENAR! JAWABAN TES TEPAT!", "❌ Belum Tepat (Cek Sheet Akhir: 99_KUNCI_JAWABAN)"))
B47: Toko Aksesoris | C47: 78
B48: Toko Servis | C48: 95
B51: 📝 SOAL TES #5: Kasus Akademik Sekolah & Layanan Publik
B52: Label | C52: Data | E52: Persoalan Tes #5: Periksa nomor urut posisi sel C53 menggunakan fungsi referensi COLUMN!
...

Sheet ROWS
B1: 📊 #008 — RUMUS EXCEL: ROWS | Kategori: 3. Lookup & Referensi
B2: 1 Rumus = 1 Contoh Soal + Jawaban Benar & 5 Soal Tes Mandiri (Kunci Jawaban Ada di Sheet Paling Terakhir) | F2: ⬅️ Ke Daftar Isi (00_DAFTAR_ISI) | G2: 🔑 Ke Kunci Jawaban (Sheet Akhir)
B4: 1️⃣ IDENTITAS RUMUS & FUNGSINYA BUAT APA? (ROWS)
B5: Nama Rumus Excel | C5: =ROWS(...)
B6: Sintaks / Pola Umum | C6: =ROWS(range_tabel)
B7: 👶 Fungsinya Buat Apa? | C7: Menghitung ada berapa total baris di dalam suatu blok tabel.
B9: 2️⃣ 1 CONTOH SOAL & CONTOH JAWABAN BENAR (PELAJARI POLA RUMUS ROWS DI SINI)
B10: Label | C10: Data | E10: ✅ 1 CONTOH SOAL BESERTA CONTOH RUMUS & HASIL JAWABAN BENAR:
B11: Simulasi Unit A | C11: 500000 | E11: Contoh Soal: | F11: Hitung jumlah dimensi blok tabel B11:C14 menggunakan fungsi ROWS!
B12: Simulasi Unit B | C12: 750000 | E12: Contoh Rumus Benar: | F12: '=ROWS(B11:C14)
B13: Simulasi Unit C | C13: 600000 | E13: Contoh Hasil Benar: | F13: =ROWS(B11:C14)
B14: Simulasi Unit D | C14: 950000
B16: 3️⃣ 5 SOAL TES DUNIA NYATA — KERJAKAN DI KOTAK KUNING (TANPA KUNCI RUMUS / HASIL DI SINI!)
B17: 📌 Catatan Tes: Soal Tes #1 s/d #5 di bawah ini tidak menampilkan kunci rumus maupun hasil. Kunci jawaban lengkap tersedia di sheet paling terakhir (99_KUNCI_JAWABAN).
B19: 📝 SOAL TES #1: Kasus Keuangan & Akuntansi Kantor
B20: Label | C20: Data | E20: Persoalan Tes #1: Hitung jumlah dimensi blok tabel B21:C24 menggunakan fungsi ROWS!
B21: Cabang Jakarta | C21: 1250000 | E21: ✏️ KETIK RUMUS JAWABAN TES DI BAWAH: | F21: 📌 STATUS KOREKSI JAWABAN TES:
B22: Cabang Bandung | C22: 1850000 | F22: =IF(ISBLANK(E22), "⏳ Belum Diisi (Ketik Rumus di Sel Kuning E22)", IF(E22='99_KUNCI_JAWABAN'!F40, "✅ BENAR! JAWABAN TES TEPAT!", "❌ Belum Tepat (Cek Sheet Akhir: 99_KUNCI_JAWABAN)"))
B23: Cabang Surabaya | C23: 2100000
B24: Cabang Medan | C24: 1600000
B27: 📝 SOAL TES #2: Kasus HRD, Gaji & Lembur Karyawan
B28: Label | C28: Data | E28: Persoalan Tes #2: Hitung jumlah dimensi blok tabel B29:C32 menggunakan fungsi ROWS!
B29: Budi Santoso | C29: 4500000 | E29: ✏️ KETIK RUMUS JAWABAN TES DI BAWAH: | F29: 📌 STATUS KOREKSI JAWABAN TES:
B30: Siti Aminah | C30: 5200000 | F30: =IF(ISBLANK(E30), "⏳ Belum Diisi (Ketik Rumus di Sel Kuning E30)", IF(E30='99_KUNCI_JAWABAN'!F41, "✅ BENAR! JAWABAN TES TEPAT!", "❌ Belum Tepat (Cek Sheet Akhir: 99_KUNCI_JAWABAN)"))
B31: Andi Pratama | C31: 4800000
B32: Rina Wijaya | C32: 6100000
B35: 📝 SOAL TES #3: Kasus Logistik & Stok Gudang Utama
B36: Label | C36: Data | E36: Persoalan Tes #3: Hitung jumlah dimensi blok tabel B37:C40 menggunakan fungsi ROWS!
B37: Gudang Blok A | C37: 240 | E37: ✏️ KETIK RUMUS JAWABAN TES DI BAWAH: | F37: 📌 STATUS KOREKSI JAWABAN TES:
B38: Gudang Blok B | C38: 380 | F38: =IF(ISBLANK(E38), "⏳ Belum Diisi (Ketik Rumus di Sel Kuning E38)", IF(E38='99_KUNCI_JAWABAN'!F42, "✅ BENAR! JAWABAN TES TEPAT!", "❌ Belum Tepat (Cek Sheet Akhir: 99_KUNCI_JAWABAN)"))
B39: Gudang Blok C | C39: 195
B40: Gudang Blok D | C40: 425
B43: 📝 SOAL TES #4: Kasus Penjualan Retail & Target Toko
B44: Label | C44: Data | E44: Persoalan Tes #4: Hitung jumlah dimensi blok tabel B45:C48 menggunakan fungsi ROWS!
B45: Toko Elektronik | C45: 85 | E45: ✏️ KETIK RUMUS JAWABAN TES DI BAWAH: | F45: 📌 STATUS KOREKSI JAWABAN TES:
B46: Toko Komputer | C46: 92 | F46: =IF(ISBLANK(E46), "⏳ Belum Diisi (Ketik Rumus di Sel Kuning E46)", IF(E46='99_KUNCI_JAWABAN'!F43, "✅ BENAR! JAWABAN TES TEPAT!", "❌ Belum Tepat (Cek Sheet Akhir: 99_KUNCI_JAWABAN)"))
B47: Toko Aksesoris | C47: 78
B48: Toko Servis | C48: 95
B51: 📝 SOAL TES #5: Kasus Akademik Sekolah & Layanan Publik
B52: Label | C52: Data | E52: Persoalan Tes #5: Hitung jumlah dimensi blok tabel B53:C56 menggunakan fungsi ROWS!
...

Sheet COLUMNS
B1: 📊 #009 — RUMUS EXCEL: COLUMNS | Kategori: 3. Lookup & Referensi
B2: 1 Rumus = 1 Contoh Soal + Jawaban Benar & 5 Soal Tes Mandiri (Kunci Jawaban Ada di Sheet Paling Terakhir) | F2: ⬅️ Ke Daftar Isi (00_DAFTAR_ISI) | G2: 🔑 Ke Kunci Jawaban (Sheet Akhir)
B4: 1️⃣ IDENTITAS RUMUS & FUNGSINYA BUAT APA? (COLUMNS)
B5: Nama Rumus Excel | C5: =COLUMNS(...)
B6: Sintaks / Pola Umum | C6: =COLUMNS(range_tabel)
B7: 👶 Fungsinya Buat Apa? | C7: Menghitung ada berapa total kolom menyamping di dalam suatu blok tabel.
B9: 2️⃣ 1 CONTOH SOAL & CONTOH JAWABAN BENAR (PELAJARI POLA RUMUS COLUMNS DI SINI)
B10: Label | C10: Data | E10: ✅ 1 CONTOH SOAL BESERTA CONTOH RUMUS & HASIL JAWABAN BENAR:
B11: Simulasi Unit A | C11: 500000 | E11: Contoh Soal: | F11: Hitung jumlah dimensi blok tabel B11:C14 menggunakan fungsi COLUMNS!
B12: Simulasi Unit B | C12: 750000 | E12: Contoh Rumus Benar: | F12: '=COLUMNS(B11:C14)
B13: Simulasi Unit C | C13: 600000 | E13: Contoh Hasil Benar: | F13: =COLUMNS(B11:C14)
B14: Simulasi Unit D | C14: 950000
B16: 3️⃣ 5 SOAL TES DUNIA NYATA — KERJAKAN DI KOTAK KUNING (TANPA KUNCI RUMUS / HASIL DI SINI!)
B17: 📌 Catatan Tes: Soal Tes #1 s/d #5 di bawah ini tidak menampilkan kunci rumus maupun hasil. Kunci jawaban lengkap tersedia di sheet paling terakhir (99_KUNCI_JAWABAN).
B19: 📝 SOAL TES #1: Kasus Keuangan & Akuntansi Kantor
B20: Label | C20: Data | E20: Persoalan Tes #1: Hitung jumlah dimensi blok tabel B21:C24 menggunakan fungsi COLUMNS!
B21: Cabang Jakarta | C21: 1250000 | E21: ✏️ KETIK RUMUS JAWABAN TES DI BAWAH: | F21: 📌 STATUS KOREKSI JAWABAN TES:
B22: Cabang Bandung | C22: 1850000 | F22: =IF(ISBLANK(E22), "⏳ Belum Diisi (Ketik Rumus di Sel Kuning E22)", IF(E22='99_KUNCI_JAWABAN'!F45, "✅ BENAR! JAWABAN TES TEPAT!", "❌ Belum Tepat (Cek Sheet Akhir: 99_KUNCI_JAWABAN)"))
B23: Cabang Surabaya | C23: 2100000
B24: Cabang Medan | C24: 1600000
B27: 📝 SOAL TES #2: Kasus HRD, Gaji & Lembur Karyawan
B28: Label | C28: Data | E28: Persoalan Tes #2: Hitung jumlah dimensi blok tabel B29:C32 menggunakan fungsi COLUMNS!
B29: Budi Santoso | C29: 4500000 | E29: ✏️ KETIK RUMUS JAWABAN TES DI BAWAH: | F29: 📌 STATUS KOREKSI JAWABAN TES:
B30: Siti Aminah | C30: 5200000 | F30: =IF(ISBLANK(E30), "⏳ Belum Diisi (Ketik Rumus di Sel Kuning E30)", IF(E30='99_KUNCI_JAWABAN'!F46, "✅ BENAR! JAWABAN TES TEPAT!", "❌ Belum Tepat (Cek Sheet Akhir: 99_KUNCI_JAWABAN)"))
B31: Andi Pratama | C31: 4800000
B32: Rina Wijaya | C32: 6100000
B35: 📝 SOAL TES #3: Kasus Logistik & Stok Gudang Utama
B36: Label | C36: Data | E36: Persoalan Tes #3: Hitung jumlah dimensi blok tabel B37:C40 menggunakan fungsi COLUMNS!
B37: Gudang Blok A | C37: 240 | E37: ✏️ KETIK RUMUS JAWABAN TES DI BAWAH: | F37: 📌 STATUS KOREKSI JAWABAN TES:
B38: Gudang Blok B | C38: 380 | F38: =IF(ISBLANK(E38), "⏳ Belum Diisi (Ketik Rumus di Sel Kuning E38)", IF(E38='99_KUNCI_JAWABAN'!F47, "✅ BENAR! JAWABAN TES TEPAT!", "❌ Belum Tepat (Cek Sheet Akhir: 99_KUNCI_JAWABAN)"))
B39: Gudang Blok C | C39: 195
B40: Gudang Blok D | C40: 425
B43: 📝 SOAL TES #4: Kasus Penjualan Retail & Target Toko
B44: Label | C44: Data | E44: Persoalan Tes #4: Hitung jumlah dimensi blok tabel B45:C48 menggunakan fungsi COLUMNS!
B45: Toko Elektronik | C45: 85 | E45: ✏️ KETIK RUMUS JAWABAN TES DI BAWAH: | F45: 📌 STATUS KOREKSI JAWABAN TES:
B46: Toko Komputer | C46: 92 | F46: =IF(ISBLANK(E46), "⏳ Belum Diisi (Ketik Rumus di Sel Kuning E46)", IF(E46='99_KUNCI_JAWABAN'!F48, "✅ BENAR! JAWABAN TES TEPAT!", "❌ Belum Tepat (Cek Sheet Akhir: 99_KUNCI_JAWABAN)"))
B47: Toko Aksesoris | C47: 78
B48: Toko Servis | C48: 95
B51: 📝 SOAL TES #5: Kasus Akademik Sekolah & Layanan Publik
B52: Label | C52: Data | E52: Persoalan Tes #5: Hitung jumlah dimensi blok tabel B53:C56 menggunakan fungsi COLUMNS!
...

Sheet ADDRESS
B1: 📊 #010 — RUMUS EXCEL: ADDRESS | Kategori: 3. Lookup & Referensi
B2: 1 Rumus = 1 Contoh Soal + Jawaban Benar & 5 Soal Tes Mandiri (Kunci Jawaban Ada di Sheet Paling Terakhir) | F2: ⬅️ Ke Daftar Isi (00_DAFTAR_ISI) | G2: 🔑 Ke Kunci Jawaban (Sheet Akhir)
B4: 1️⃣ IDENTITAS RUMUS & FUNGSINYA BUAT APA? (ADDRESS)
B5: Nama Rumus Excel | C5: =ADDRESS(...)
B6: Sintaks / Pola Umum | C6: =ADDRESS(nomor_baris, nomor_kolom)
B7: 👶 Fungsinya Buat Apa? | C7: Merakit teks alamat koordinat sel (seperti $C$19) dari angka nomor baris dan nomor kolom.
B9: 2️⃣ 1 CONTOH SOAL & CONTOH JAWABAN BENAR (PELAJARI POLA RUMUS ADDRESS DI SINI)
B10: Label | C10: Data | E10: ✅ 1 CONTOH SOAL BESERTA CONTOH RUMUS & HASIL JAWABAN BENAR:
B11: Simulasi Unit A | C11: 500000 | E11: Contoh Soal: | F11: Bentuk teks alamat koordinat sel untuk nomor baris 11 dan nomor kolom 3 menggunakan fungsi ADDRESS!
B12: Simulasi Unit B | C12: 750000 | E12: Contoh Rumus Benar: | F12: '=ADDRESS(11, 3)
B13: Simulasi Unit C | C13: 600000 | E13: Contoh Hasil Benar: | F13: =ADDRESS(11, 3)
B14: Simulasi Unit D | C14: 950000
B16: 3️⃣ 5 SOAL TES DUNIA NYATA — KERJAKAN DI KOTAK KUNING (TANPA KUNCI RUMUS / HASIL DI SINI!)
B17: 📌 Catatan Tes: Soal Tes #1 s/d #5 di bawah ini tidak menampilkan kunci rumus maupun hasil. Kunci jawaban lengkap tersedia di sheet paling terakhir (99_KUNCI_JAWABAN).
B19: 📝 SOAL TES #1: Kasus Keuangan & Akuntansi Kantor
B20: Label | C20: Data | E20: Persoalan Tes #1: Bentuk teks alamat koordinat sel untuk nomor baris 21 dan nomor kolom 3 menggunakan fungsi ADDRESS!
B21: Cabang Jakarta | C21: 1250000 | E21: ✏️ KETIK RUMUS JAWABAN TES DI BAWAH: | F21: 📌 STATUS KOREKSI JAWABAN TES:
B22: Cabang Bandung | C22: 1850000 | F22: =IF(ISBLANK(E22), "⏳ Belum Diisi (Ketik Rumus di Sel Kuning E22)", IF(E22='99_KUNCI_JAWABAN'!F50, "✅ BENAR! JAWABAN TES TEPAT!", "❌ Belum Tepat (Cek Sheet Akhir: 99_KUNCI_JAWABAN)"))
B23: Cabang Surabaya | C23: 2100000
B24: Cabang Medan | C24: 1600000
B27: 📝 SOAL TES #2: Kasus HRD, Gaji & Lembur Karyawan
B28: Label | C28: Data | E28: Persoalan Tes #2: Bentuk teks alamat koordinat sel untuk nomor baris 29 dan nomor kolom 3 menggunakan fungsi ADDRESS!
B29: Budi Santoso | C29: 4500000 | E29: ✏️ KETIK RUMUS JAWABAN TES DI BAWAH: | F29: 📌 STATUS KOREKSI JAWABAN TES:
B30: Siti Aminah | C30: 5200000 | F30: =IF(ISBLANK(E30), "⏳ Belum Diisi (Ketik Rumus di Sel Kuning E30)", IF(E30='99_KUNCI_JAWABAN'!F51, "✅ BENAR! JAWABAN TES TEPAT!", "❌ Belum Tepat (Cek Sheet Akhir: 99_KUNCI_JAWABAN)"))
B31: Andi Pratama | C31: 4800000
B32: Rina Wijaya | C32: 6100000
B35: 📝 SOAL TES #3: Kasus Logistik & Stok Gudang Utama
B36: Label | C36: Data | E36: Persoalan Tes #3: Bentuk teks alamat koordinat sel untuk nomor baris 37 dan nomor kolom 3 menggunakan fungsi ADDRESS!
B37: Gudang Blok A | C37: 240 | E37: ✏️ KETIK RUMUS JAWABAN TES DI BAWAH: | F37: 📌 STATUS KOREKSI JAWABAN TES:
B38: Gudang Blok B | C38: 380 | F38: =IF(ISBLANK(E38), "⏳ Belum Diisi (Ketik Rumus di Sel Kuning E38)", IF(E38='99_KUNCI_JAWABAN'!F52, "✅ BENAR! JAWABAN TES TEPAT!", "❌ Belum Tepat (Cek Sheet Akhir: 99_KUNCI_JAWABAN)"))
B39: Gudang Blok C | C39: 195
B40: Gudang Blok D | C40: 425
B43: 📝 SOAL TES #4: Kasus Penjualan Retail & Target Toko
B44: Label | C44: Data | E44: Persoalan Tes #4: Bentuk teks alamat koordinat sel untuk nomor baris 45 dan nomor kolom 3 menggunakan fungsi ADDRESS!
B45: Toko Elektronik | C45: 85 | E45: ✏️ KETIK RUMUS JAWABAN TES DI BAWAH: | F45: 📌 STATUS KOREKSI JAWABAN TES:
B46: Toko Komputer | C46: 92 | F46: =IF(ISBLANK(E46), "⏳ Belum Diisi (Ketik Rumus di Sel Kuning E46)", IF(E46='99_KUNCI_JAWABAN'!F53, "✅ BENAR! JAWABAN TES TEPAT!", "❌ Belum Tepat (Cek Sheet Akhir: 99_KUNCI_JAWABAN)"))
B47: Toko Aksesoris | C47: 78
B48: Toko Servis | C48: 95
B51: 📝 SOAL TES #5: Kasus Akademik Sekolah & Layanan Publik
B52: Label | C52: Data | E52: Persoalan Tes #5: Bentuk teks alamat koordinat sel untuk nomor baris 53 dan nomor kolom 3 menggunakan fungsi ADDRESS!
...

Sheet OFFSET
B1: 📊 #011 — RUMUS EXCEL: OFFSET | Kategori: 3. Lookup & Referensi
B2: 1 Rumus = 1 Contoh Soal + Jawaban Benar & 5 Soal Tes Mandiri (Kunci Jawaban Ada di Sheet Paling Terakhir) | F2: ⬅️ Ke Daftar Isi (00_DAFTAR_ISI) | G2: 🔑 Ke Kunci Jawaban (Sheet Akhir)
B4: 1️⃣ IDENTITAS RUMUS & FUNGSINYA BUAT APA? (OFFSET)
B5: Nama Rumus Excel | C5: =OFFSET(...)
B6: Sintaks / Pola Umum | C6: =OFFSET(sel_awal, geser_baris, geser_kolom)
B7: 👶 Fungsinya Buat Apa? | C7: Mengambil data dari sel lain dengan cara melangkah/bergeser sejumlah baris ke bawah dan kolom ke samping dari titik awal.
B9: 2️⃣ 1 CONTOH SOAL & CONTOH JAWABAN BENAR (PELAJARI POLA RUMUS OFFSET DI SINI)
B10: Label | C10: Data | E10: ✅ 1 CONTOH SOAL BESERTA CONTOH RUMUS & HASIL JAWABAN BENAR:
B11: Simulasi Unit A | C11: 500000 | E11: Contoh Soal: | F11: Ambil nilai sel yang bergeser 1 baris ke bawah dan 0 kolom ke samping dari titik awal C11 menggunakan fungsi OFFSET!
B12: Simulasi Unit B | C12: 750000 | E12: Contoh Rumus Benar: | F12: '=OFFSET(C11, 1, 0)
B13: Simulasi Unit C | C13: 600000 | E13: Contoh Hasil Benar: | F13: =OFFSET(C11, 1, 0)
B14: Simulasi Unit D | C14: 950000
B16: 3️⃣ 5 SOAL TES DUNIA NYATA — KERJAKAN DI KOTAK KUNING (TANPA KUNCI RUMUS / HASIL DI SINI!)
B17: 📌 Catatan Tes: Soal Tes #1 s/d #5 di bawah ini tidak menampilkan kunci rumus maupun hasil. Kunci jawaban lengkap tersedia di sheet paling terakhir (99_KUNCI_JAWABAN).
B19: 📝 SOAL TES #1: Kasus Keuangan & Akuntansi Kantor
B20: Label | C20: Data | E20: Persoalan Tes #1: Ambil nilai sel yang bergeser 1 baris ke bawah dan 0 kolom ke samping dari titik awal C21 menggunakan fungsi OFFSET!
B21: Cabang Jakarta | C21: 1250000 | E21: ✏️ KETIK RUMUS JAWABAN TES DI BAWAH: | F21: 📌 STATUS KOREKSI JAWABAN TES:
B22: Cabang Bandung | C22: 1850000 | F22: =IF(ISBLANK(E22), "⏳ Belum Diisi (Ketik Rumus di Sel Kuning E22)", IF(E22='99_KUNCI_JAWABAN'!F55, "✅ BENAR! JAWABAN TES TEPAT!", "❌ Belum Tepat (Cek Sheet Akhir: 99_KUNCI_JAWABAN)"))
B23: Cabang Surabaya | C23: 2100000
B24: Cabang Medan | C24: 1600000
B27: 📝 SOAL TES #2: Kasus HRD, Gaji & Lembur Karyawan
B28: Label | C28: Data | E28: Persoalan Tes #2: Ambil nilai sel yang bergeser 1 baris ke bawah dan 0 kolom ke samping dari titik awal C29 menggunakan fungsi OFFSET!
B29: Budi Santoso | C29: 4500000 | E29: ✏️ KETIK RUMUS JAWABAN TES DI BAWAH: | F29: 📌 STATUS KOREKSI JAWABAN TES:
B30: Siti Aminah | C30: 5200000 | F30: =IF(ISBLANK(E30), "⏳ Belum Diisi (Ketik Rumus di Sel Kuning E30)", IF(E30='99_KUNCI_JAWABAN'!F56, "✅ BENAR! JAWABAN TES TEPAT!", "❌ Belum Tepat (Cek Sheet Akhir: 99_KUNCI_JAWABAN)"))
B31: Andi Pratama | C31: 4800000
B32: Rina Wijaya | C32: 6100000
B35: 📝 SOAL TES #3: Kasus Logistik & Stok Gudang Utama
B36: Label | C36: Data | E36: Persoalan Tes #3: Ambil nilai sel yang bergeser 1 baris ke bawah dan 0 kolom ke samping dari titik awal C37 menggunakan fungsi OFFSET!
B37: Gudang Blok A | C37: 240 | E37: ✏️ KETIK RUMUS JAWABAN TES DI BAWAH: | F37: 📌 STATUS KOREKSI JAWABAN TES:
B38: Gudang Blok B | C38: 380 | F38: =IF(ISBLANK(E38), "⏳ Belum Diisi (Ketik Rumus di Sel Kuning E38)", IF(E38='99_KUNCI_JAWABAN'!F57, "✅ BENAR! JAWABAN TES TEPAT!", "❌ Belum Tepat (Cek Sheet Akhir: 99_KUNCI_JAWABAN)"))
B39: Gudang Blok C | C39: 195
B40: Gudang Blok D | C40: 425
B43: 📝 SOAL TES #4: Kasus Penjualan Retail & Target Toko
B44: Label | C44: Data | E44: Persoalan Tes #4: Ambil nilai sel yang bergeser 1 baris ke bawah dan 0 kolom ke samping dari titik awal C45 menggunakan fungsi OFFSET!
B45: Toko Elektronik | C45: 85 | E45: ✏️ KETIK RUMUS JAWABAN TES DI BAWAH: | F45: 📌 STATUS KOREKSI JAWABAN TES:
B46: Toko Komputer | C46: 92 | F46: =IF(ISBLANK(E46), "⏳ Belum Diisi (Ketik Rumus di Sel Kuning E46)", IF(E46='99_KUNCI_JAWABAN'!F58, "✅ BENAR! JAWABAN TES TEPAT!", "❌ Belum Tepat (Cek Sheet Akhir: 99_KUNCI_JAWABAN)"))
B47: Toko Aksesoris | C47: 78
B48: Toko Servis | C48: 95
B51: 📝 SOAL TES #5: Kasus Akademik Sekolah & Layanan Publik
B52: Label | C52: Data | E52: Persoalan Tes #5: Ambil nilai sel yang bergeser 1 baris ke bawah dan 0 kolom ke samping dari titik awal C53 menggunakan fungsi OFFSET!
...

Sheet INDIRECT
B1: 📊 #012 — RUMUS EXCEL: INDIRECT | Kategori: 3. Lookup & Referensi
B2: 1 Rumus = 1 Contoh Soal + Jawaban Benar & 5 Soal Tes Mandiri (Kunci Jawaban Ada di Sheet Paling Terakhir) | F2: ⬅️ Ke Daftar Isi (00_DAFTAR_ISI) | G2: 🔑 Ke Kunci Jawaban (Sheet Akhir)
B4: 1️⃣ IDENTITAS RUMUS & FUNGSINYA BUAT APA? (INDIRECT)
B5: Nama Rumus Excel | C5: =INDIRECT(...)
B6: Sintaks / Pola Umum | C6: =INDIRECT(teks_alamat_sel)
B7: 👶 Fungsinya Buat Apa? | C7: Mengubah tulisan teks biasa yang berisi alamat sel menjadi rujukan sel hidup yang diambil nilainya!
B9: 2️⃣ 1 CONTOH SOAL & CONTOH JAWABAN BENAR (PELAJARI POLA RUMUS INDIRECT DI SINI)
B10: Label | C10: Data | E10: ✅ 1 CONTOH SOAL BESERTA CONTOH RUMUS & HASIL JAWABAN BENAR:
B11: Simulasi Unit A | C11: 500000 | E11: Contoh Soal: | F11: Ambil isi sel berdasarkan teks alamat "C11" menggunakan fungsi INDIRECT!
B12: Simulasi Unit B | C12: 750000 | E12: Contoh Rumus Benar: | F12: '=INDIRECT("C11")
B13: Simulasi Unit C | C13: 600000 | E13: Contoh Hasil Benar: | F13: =INDIRECT("C11")
B14: Simulasi Unit D | C14: 950000
B16: 3️⃣ 5 SOAL TES DUNIA NYATA — KERJAKAN DI KOTAK KUNING (TANPA KUNCI RUMUS / HASIL DI SINI!)
B17: 📌 Catatan Tes: Soal Tes #1 s/d #5 di bawah ini tidak menampilkan kunci rumus maupun hasil. Kunci jawaban lengkap tersedia di sheet paling terakhir (99_KUNCI_JAWABAN).
B19: 📝 SOAL TES #1: Kasus Keuangan & Akuntansi Kantor
B20: Label | C20: Data | E20: Persoalan Tes #1: Ambil isi sel berdasarkan teks alamat "C21" menggunakan fungsi INDIRECT!
B21: Cabang Jakarta | C21: 1250000 | E21: ✏️ KETIK RUMUS JAWABAN TES DI BAWAH: | F21: 📌 STATUS KOREKSI JAWABAN TES:
B22: Cabang Bandung | C22: 1850000 | F22: =IF(ISBLANK(E22), "⏳ Belum Diisi (Ketik Rumus di Sel Kuning E22)", IF(E22='99_KUNCI_JAWABAN'!F60, "✅ BENAR! JAWABAN TES TEPAT!", "❌ Belum Tepat (Cek Sheet Akhir: 99_KUNCI_JAWABAN)"))
B23: Cabang Surabaya | C23: 2100000
B24: Cabang Medan | C24: 1600000
B27: 📝 SOAL TES #2: Kasus HRD, Gaji & Lembur Karyawan
B28: Label | C28: Data | E28: Persoalan Tes #2: Ambil isi sel berdasarkan teks alamat "C29" menggunakan fungsi INDIRECT!
B29: Budi Santoso | C29: 4500000 | E29: ✏️ KETIK RUMUS JAWABAN TES DI BAWAH: | F29: 📌 STATUS KOREKSI JAWABAN TES:
B30: Siti Aminah | C30: 5200000 | F30: =IF(ISBLANK(E30), "⏳ Belum Diisi (Ketik Rumus di Sel Kuning E30)", IF(E30='99_KUNCI_JAWABAN'!F61, "✅ BENAR! JAWABAN TES TEPAT!", "❌ Belum Tepat (Cek Sheet Akhir: 99_KUNCI_JAWABAN)"))
B31: Andi Pratama | C31: 4800000
B32: Rina Wijaya | C32: 6100000
B35: 📝 SOAL TES #3: Kasus Logistik & Stok Gudang Utama
B36: Label | C36: Data | E36: Persoalan Tes #3: Ambil isi sel berdasarkan teks alamat "C37" menggunakan fungsi INDIRECT!
B37: Gudang Blok A | C37: 240 | E37: ✏️ KETIK RUMUS JAWABAN TES DI BAWAH: | F37: 📌 STATUS KOREKSI JAWABAN TES:
B38: Gudang Blok B | C38: 380 | F38: =IF(ISBLANK(E38), "⏳ Belum Diisi (Ketik Rumus di Sel Kuning E38)", IF(E38='99_KUNCI_JAWABAN'!F62, "✅ BENAR! JAWABAN TES TEPAT!", "❌ Belum Tepat (Cek Sheet Akhir: 99_KUNCI_JAWABAN)"))
B39: Gudang Blok C | C39: 195
B40: Gudang Blok D | C40: 425
B43: 📝 SOAL TES #4: Kasus Penjualan Retail & Target Toko
B44: Label | C44: Data | E44: Persoalan Tes #4: Ambil isi sel berdasarkan teks alamat "C45" menggunakan fungsi INDIRECT!
B45: Toko Elektronik | C45: 85 | E45: ✏️ KETIK RUMUS JAWABAN TES DI BAWAH: | F45: 📌 STATUS KOREKSI JAWABAN TES:
B46: Toko Komputer | C46: 92 | F46: =IF(ISBLANK(E46), "⏳ Belum Diisi (Ketik Rumus di Sel Kuning E46)", IF(E46='99_KUNCI_JAWABAN'!F63, "✅ BENAR! JAWABAN TES TEPAT!", "❌ Belum Tepat (Cek Sheet Akhir: 99_KUNCI_JAWABAN)"))
B47: Toko Aksesoris | C47: 78
B48: Toko Servis | C48: 95
B51: 📝 SOAL TES #5: Kasus Akademik Sekolah & Layanan Publik
B52: Label | C52: Data | E52: Persoalan Tes #5: Ambil isi sel berdasarkan teks alamat "C53" menggunakan fungsi INDIRECT!
...

Sheet LEFT
B1: 📊 #013 — RUMUS EXCEL: LEFT | Kategori: 4. Pengolahan Teks
B2: 1 Rumus = 1 Contoh Soal + Jawaban Benar & 5 Soal Tes Mandiri (Kunci Jawaban Ada di Sheet Paling Terakhir) | F2: ⬅️ Ke Daftar Isi (00_DAFTAR_ISI) | G2: 🔑 Ke Kunci Jawaban (Sheet Akhir)
B4: 1️⃣ IDENTITAS RUMUS & FUNGSINYA BUAT APA? (LEFT)
B5: Nama Rumus Excel | C5: =LEFT(...)
B6: Sintaks / Pola Umum | C6: =LEFT(teks, jumlah_karakter)
B7: 👶 Fungsinya Buat Apa? | C7: Memotong dan mengambil sejumlah huruf dari sebelah KIRI (awal kata/kode barang).
B9: 2️⃣ 1 CONTOH SOAL & CONTOH JAWABAN BENAR (PELAJARI POLA RUMUS LEFT DI SINI)
B10: Nama Gudang | C10: Kode SKU Barang | E10: ✅ 1 CONTOH SOAL BESERTA CONTOH RUMUS & HASIL JAWABAN BENAR:
B11: Simulasi Unit A | C11: JKT-105-A | E11: Contoh Soal: | F11: Ekstrak 3 karakter dari kode SKU di sel C11 ("JKT-105-A") menggunakan fungsi teks LEFT!
B12: Simulasi Unit B | C12: BDG-205-B | E12: Contoh Rumus Benar: | F12: '=LEFT(C11, 3)
B13: Simulasi Unit C | C13: SBY-310-C | E13: Contoh Hasil Benar: | F13: =LEFT(C11, 3)
B14: Simulasi Unit D | C14: MDN-415-D
B16: 3️⃣ 5 SOAL TES DUNIA NYATA — KERJAKAN DI KOTAK KUNING (TANPA KUNCI RUMUS / HASIL DI SINI!)
B17: 📌 Catatan Tes: Soal Tes #1 s/d #5 di bawah ini tidak menampilkan kunci rumus maupun hasil. Kunci jawaban lengkap tersedia di sheet paling terakhir (99_KUNCI_JAWABAN).
B19: 📝 SOAL TES #1: Kasus Keuangan & Akuntansi Kantor
B20: Nama Gudang | C20: Kode SKU Barang | E20: Persoalan Tes #1: Ekstrak 3 karakter dari kode SKU di sel C21 ("JKT-100-A") menggunakan fungsi teks LEFT!
B21: Cabang Jakarta | C21: JKT-100-A | E21: ✏️ KETIK RUMUS JAWABAN TES DI BAWAH: | F21: 📌 STATUS KOREKSI JAWABAN TES:
B22: Cabang Bandung | C22: BDG-205-B | F22: =IF(ISBLANK(E22), "⏳ Belum Diisi (Ketik Rumus di Sel Kuning E22)", IF(E22='99_KUNCI_JAWABAN'!F65, "✅ BENAR! JAWABAN TES TEPAT!", "❌ Belum Tepat (Cek Sheet Akhir: 99_KUNCI_JAWABAN)"))
B23: Cabang Surabaya | C23: SBY-310-C
B24: Cabang Medan | C24: MDN-415-D
B27: 📝 SOAL TES #2: Kasus HRD, Gaji & Lembur Karyawan
B28: Nama Gudang | C28: Kode SKU Barang | E28: Persoalan Tes #2: Ekstrak 3 karakter dari kode SKU di sel C29 ("JKT-101-A") menggunakan fungsi teks LEFT!
B29: Budi Santoso | C29: JKT-101-A | E29: ✏️ KETIK RUMUS JAWABAN TES DI BAWAH: | F29: 📌 STATUS KOREKSI JAWABAN TES:
B30: Siti Aminah | C30: BDG-205-B | F30: =IF(ISBLANK(E30), "⏳ Belum Diisi (Ketik Rumus di Sel Kuning E30)", IF(E30='99_KUNCI_JAWABAN'!F66, "✅ BENAR! JAWABAN TES TEPAT!", "❌ Belum Tepat (Cek Sheet Akhir: 99_KUNCI_JAWABAN)"))
B31: Andi Pratama | C31: SBY-310-C
B32: Rina Wijaya | C32: MDN-415-D
B35: 📝 SOAL TES #3: Kasus Logistik & Stok Gudang Utama
B36: Nama Gudang | C36: Kode SKU Barang | E36: Persoalan Tes #3: Ekstrak 3 karakter dari kode SKU di sel C37 ("JKT-102-A") menggunakan fungsi teks LEFT!
B37: Gudang Blok A | C37: JKT-102-A | E37: ✏️ KETIK RUMUS JAWABAN TES DI BAWAH: | F37: 📌 STATUS KOREKSI JAWABAN TES:
B38: Gudang Blok B | C38: BDG-205-B | F38: =IF(ISBLANK(E38), "⏳ Belum Diisi (Ketik Rumus di Sel Kuning E38)", IF(E38='99_KUNCI_JAWABAN'!F67, "✅ BENAR! JAWABAN TES TEPAT!", "❌ Belum Tepat (Cek Sheet Akhir: 99_KUNCI_JAWABAN)"))
B39: Gudang Blok C | C39: SBY-310-C
B40: Gudang Blok D | C40: MDN-415-D
B43: 📝 SOAL TES #4: Kasus Penjualan Retail & Target Toko
B44: Nama Gudang | C44: Kode SKU Barang | E44: Persoalan Tes #4: Ekstrak 3 karakter dari kode SKU di sel C45 ("JKT-103-A") menggunakan fungsi teks LEFT!
